2025-10-31 03:35:55,399 - MQTTIngestor - INFO - Starting MQTT Ingestor...
2025-10-31 03:35:55,466 - MQTTIngestor - CRITICAL - Failed to connect to database using SQLAlchemy: (psycopg2.OperationalError) connection to server at "postgres" (172.18.0.3), port 5432 failed: FATAL:  password authentication failed for user "dt_user"

(Background on this error at: https://sqlalche.me/e/20/e3q8)
Traceback (most recent call last):
  File "/usr/local/lib/python3.12/site-packages/sqlalchemy/engine/base.py", line 146, in __init__
    self._dbapi_connection = engine.raw_connection()
                             ^^^^^^^^^^^^^^^^^^^^^^^
  File "/usr/local/lib/python3.12/site-packages/sqlalchemy/engine/base.py", line 3302, in raw_connection
    return self.pool.connect()
           ^^^^^^^^^^^^^^^^^^^
  File "/usr/local/lib/python3.12/site-packages/sqlalchemy/pool/base.py", line 449, in connect
    return _ConnectionFairy._checkout(self)
           ^^^^^^^^^^^^^^^^^^^^^^^^^^^^^^^^
  File "/usr/local/lib/python3.12/site-packages/sqlalchemy/pool/base.py", line 1263, in _checkout
    fairy = _ConnectionRecord.checkout(pool)
            ^^^^^^^^^^^^^^^^^^^^^^^^^^^^^^^^
  File "/usr/local/lib/python3.12/site-packages/sqlalchemy/pool/base.py", line 712, in checkout
    rec = pool._do_get()
          ^^^^^^^^^^^^^^
  File "/usr/local/lib/python3.12/site-packages/sqlalchemy/pool/impl.py", line 179, in _do_get
    with util.safe_reraise():
         ^^^^^^^^^^^^^^^^^^^
  File "/usr/local/lib/python3.12/site-packages/sqlalchemy/util/langhelpers.py", line 146, in __exit__
    raise exc_value.with_traceback(exc_tb)
  File "/usr/local/lib/python3.12/site-packages/sqlalchemy/pool/impl.py", line 177, in _do_get
    return self._create_connection()
           ^^^^^^^^^^^^^^^^^^^^^^^^^
  File "/usr/local/lib/python3.12/site-packages/sqlalchemy/pool/base.py", line 390, in _create_connection
    return _ConnectionRecord(self)
           ^^^^^^^^^^^^^^^^^^^^^^^
  File "/usr/local/lib/python3.12/site-packages/sqlalchemy/pool/base.py", line 674, in __init__
    self.__connect()
  File "/usr/local/lib/python3.12/site-packages/sqlalchemy/pool/base.py", line 900, in __connect
    with util.safe_reraise():
         ^^^^^^^^^^^^^^^^^^^
  File "/usr/local/lib/python3.12/site-packages/sqlalchemy/util/langhelpers.py", line 146, in __exit__
    raise exc_value.with_traceback(exc_tb)
  File "/usr/local/lib/python3.12/site-packages/sqlalchemy/pool/base.py", line 896, in __connect
    self.dbapi_connection = connection = pool._invoke_creator(self)
                                         ^^^^^^^^^^^^^^^^^^^^^^^^^^
  File "/usr/local/lib/python3.12/site-packages/sqlalchemy/engine/create.py", line 643, in connect
    return dialect.connect(*cargs, **cparams)
           ^^^^^^^^^^^^^^^^^^^^^^^^^^^^^^^^^^
  File "/usr/local/lib/python3.12/site-packages/sqlalchemy/engine/default.py", line 621, in connect
    return self.loaded_dbapi.connect(*cargs, **cparams)
           ^^^^^^^^^^^^^^^^^^^^^^^^^^^^^^^^^^^^^^^^^^^^
  File "/usr/local/lib/python3.12/site-packages/psycopg2/__init__.py", line 122, in connect
    conn = _connect(dsn, connection_factory=connection_factory, **kwasync)
           ^^^^^^^^^^^^^^^^^^^^^^^^^^^^^^^^^^^^^^^^^^^^^^^^^^^^^^^^^^^^^^^
psycopg2.OperationalError: connection to server at "postgres" (172.18.0.3), port 5432 failed: FATAL:  password authentication failed for user "dt_user"


The above exception was the direct cause of the following exception:

Traceback (most recent call last):
  File "/app/Digital_Twin/AI_MODULES/mqtt_ingestor.py", line 127, in init_database_connection
    with db_engine.connect():
         ^^^^^^^^^^^^^^^^^^^
  File "/usr/local/lib/python3.12/site-packages/sqlalchemy/engine/base.py", line 3278, in connect
    return self._connection_cls(self)
           ^^^^^^^^^^^^^^^^^^^^^^^^^^
  File "/usr/local/lib/python3.12/site-packages/sqlalchemy/engine/base.py", line 148, in __init__
    Connection._handle_dbapi_exception_noconnection(
  File "/usr/local/lib/python3.12/site-packages/sqlalchemy/engine/base.py", line 2442, in _handle_dbapi_exception_noconnection
    raise sqlalchemy_exception.with_traceback(exc_info[2]) from e
  File "/usr/local/lib/python3.12/site-packages/sqlalchemy/engine/base.py", line 146, in __init__
    self._dbapi_connection = engine.raw_connection()
                             ^^^^^^^^^^^^^^^^^^^^^^^
  File "/usr/local/lib/python3.12/site-packages/sqlalchemy/engine/base.py", line 3302, in raw_connection
    return self.pool.connect()
           ^^^^^^^^^^^^^^^^^^^
  File "/usr/local/lib/python3.12/site-packages/sqlalchemy/pool/base.py", line 449, in connect
    return _ConnectionFairy._checkout(self)
           ^^^^^^^^^^^^^^^^^^^^^^^^^^^^^^^^
  File "/usr/local/lib/python3.12/site-packages/sqlalchemy/pool/base.py", line 1263, in _checkout
    fairy = _ConnectionRecord.checkout(pool)
            ^^^^^^^^^^^^^^^^^^^^^^^^^^^^^^^^
  File "/usr/local/lib/python3.12/site-packages/sqlalchemy/pool/base.py", line 712, in checkout
    rec = pool._do_get()
          ^^^^^^^^^^^^^^
  File "/usr/local/lib/python3.12/site-packages/sqlalchemy/pool/impl.py", line 179, in _do_get
    with util.safe_reraise():
         ^^^^^^^^^^^^^^^^^^^
  File "/usr/local/lib/python3.12/site-packages/sqlalchemy/util/langhelpers.py", line 146, in __exit__
    raise exc_value.with_traceback(exc_tb)
  File "/usr/local/lib/python3.12/site-packages/sqlalchemy/pool/impl.py", line 177, in _do_get
    return self._create_connection()
           ^^^^^^^^^^^^^^^^^^^^^^^^^
  File "/usr/local/lib/python3.12/site-packages/sqlalchemy/pool/base.py", line 390, in _create_connection
    return _ConnectionRecord(self)
           ^^^^^^^^^^^^^^^^^^^^^^^
  File "/usr/local/lib/python3.12/site-packages/sqlalchemy/pool/base.py", line 674, in __init__
    self.__connect()
  File "/usr/local/lib/python3.12/site-packages/sqlalchemy/pool/base.py", line 900, in __connect
    with util.safe_reraise():
         ^^^^^^^^^^^^^^^^^^^
  File "/usr/local/lib/python3.12/site-packages/sqlalchemy/util/langhelpers.py", line 146, in __exit__
    raise exc_value.with_traceback(exc_tb)
  File "/usr/local/lib/python3.12/site-packages/sqlalchemy/pool/base.py", line 896, in __connect
    self.dbapi_connection = connection = pool._invoke_creator(self)
                                         ^^^^^^^^^^^^^^^^^^^^^^^^^^
  File "/usr/local/lib/python3.12/site-packages/sqlalchemy/engine/create.py", line 643, in connect
    return dialect.connect(*cargs, **cparams)
           ^^^^^^^^^^^^^^^^^^^^^^^^^^^^^^^^^^
  File "/usr/local/lib/python3.12/site-packages/sqlalchemy/engine/default.py", line 621, in connect
    return self.loaded_dbapi.connect(*cargs, **cparams)
           ^^^^^^^^^^^^^^^^^^^^^^^^^^^^^^^^^^^^^^^^^^^^
  File "/usr/local/lib/python3.12/site-packages/psycopg2/__init__.py", line 122, in connect
    conn = _connect(dsn, connection_factory=connection_factory, **kwasync)
           ^^^^^^^^^^^^^^^^^^^^^^^^^^^^^^^^^^^^^^^^^^^^^^^^^^^^^^^^^^^^^^^
sqlalchemy.exc.OperationalError: (psycopg2.OperationalError) connection to server at "postgres" (172.18.0.3), port 5432 failed: FATAL:  password authentication failed for user "dt_user"

(Background on this error at: https://sqlalche.me/e/20/e3q8)
2025-10-31 03:35:55,479 - MQTTIngestor - CRITICAL - Database connection failed. Exiting.
2025-10-31 03:35:57,299 - MQTTIngestor - INFO - Starting MQTT Ingestor...
2025-10-31 03:35:57,346 - MQTTIngestor - CRITICAL - Failed to connect to database using SQLAlchemy: (psycopg2.OperationalError) connection to server at "postgres" (172.18.0.3), port 5432 failed: FATAL:  password authentication failed for user "dt_user"

(Background on this error at: https://sqlalche.me/e/20/e3q8)
Traceback (most recent call last):
  File "/usr/local/lib/python3.12/site-packages/sqlalchemy/engine/base.py", line 146, in __init__
    self._dbapi_connection = engine.raw_connection()
                             ^^^^^^^^^^^^^^^^^^^^^^^
  File "/usr/local/lib/python3.12/site-packages/sqlalchemy/engine/base.py", line 3302, in raw_connection
    return self.pool.connect()
           ^^^^^^^^^^^^^^^^^^^
  File "/usr/local/lib/python3.12/site-packages/sqlalchemy/pool/base.py", line 449, in connect
    return _ConnectionFairy._checkout(self)
           ^^^^^^^^^^^^^^^^^^^^^^^^^^^^^^^^
  File "/usr/local/lib/python3.12/site-packages/sqlalchemy/pool/base.py", line 1263, in _checkout
    fairy = _ConnectionRecord.checkout(pool)
            ^^^^^^^^^^^^^^^^^^^^^^^^^^^^^^^^
  File "/usr/local/lib/python3.12/site-packages/sqlalchemy/pool/base.py", line 712, in checkout
    rec = pool._do_get()
          ^^^^^^^^^^^^^^
  File "/usr/local/lib/python3.12/site-packages/sqlalchemy/pool/impl.py", line 179, in _do_get
    with util.safe_reraise():
         ^^^^^^^^^^^^^^^^^^^
  File "/usr/local/lib/python3.12/site-packages/sqlalchemy/util/langhelpers.py", line 146, in __exit__
    raise exc_value.with_traceback(exc_tb)
  File "/usr/local/lib/python3.12/site-packages/sqlalchemy/pool/impl.py", line 177, in _do_get
    return self._create_connection()
           ^^^^^^^^^^^^^^^^^^^^^^^^^
  File "/usr/local/lib/python3.12/site-packages/sqlalchemy/pool/base.py", line 390, in _create_connection
    return _ConnectionRecord(self)
           ^^^^^^^^^^^^^^^^^^^^^^^
  File "/usr/local/lib/python3.12/site-packages/sqlalchemy/pool/base.py", line 674, in __init__
    self.__connect()
  File "/usr/local/lib/python3.12/site-packages/sqlalchemy/pool/base.py", line 900, in __connect
    with util.safe_reraise():
         ^^^^^^^^^^^^^^^^^^^
  File "/usr/local/lib/python3.12/site-packages/sqlalchemy/util/langhelpers.py", line 146, in __exit__
    raise exc_value.with_traceback(exc_tb)
  File "/usr/local/lib/python3.12/site-packages/sqlalchemy/pool/base.py", line 896, in __connect
    self.dbapi_connection = connection = pool._invoke_creator(self)
                                         ^^^^^^^^^^^^^^^^^^^^^^^^^^
  File "/usr/local/lib/python3.12/site-packages/sqlalchemy/engine/create.py", line 643, in connect
    return dialect.connect(*cargs, **cparams)
           ^^^^^^^^^^^^^^^^^^^^^^^^^^^^^^^^^^
  File "/usr/local/lib/python3.12/site-packages/sqlalchemy/engine/default.py", line 621, in connect
    return self.loaded_dbapi.connect(*cargs, **cparams)
           ^^^^^^^^^^^^^^^^^^^^^^^^^^^^^^^^^^^^^^^^^^^^
  File "/usr/local/lib/python3.12/site-packages/psycopg2/__init__.py", line 122, in connect
    conn = _connect(dsn, connection_factory=connection_factory, **kwasync)
           ^^^^^^^^^^^^^^^^^^^^^^^^^^^^^^^^^^^^^^^^^^^^^^^^^^^^^^^^^^^^^^^
psycopg2.OperationalError: connection to server at "postgres" (172.18.0.3), port 5432 failed: FATAL:  password authentication failed for user "dt_user"


The above exception was the direct cause of the following exception:

Traceback (most recent call last):
  File "/app/Digital_Twin/AI_MODULES/mqtt_ingestor.py", line 127, in init_database_connection
    with db_engine.connect():
         ^^^^^^^^^^^^^^^^^^^
  File "/usr/local/lib/python3.12/site-packages/sqlalchemy/engine/base.py", line 3278, in connect
    return self._connection_cls(self)
           ^^^^^^^^^^^^^^^^^^^^^^^^^^
  File "/usr/local/lib/python3.12/site-packages/sqlalchemy/engine/base.py", line 148, in __init__
    Connection._handle_dbapi_exception_noconnection(
  File "/usr/local/lib/python3.12/site-packages/sqlalchemy/engine/base.py", line 2442, in _handle_dbapi_exception_noconnection
    raise sqlalchemy_exception.with_traceback(exc_info[2]) from e
  File "/usr/local/lib/python3.12/site-packages/sqlalchemy/engine/base.py", line 146, in __init__
    self._dbapi_connection = engine.raw_connection()
                             ^^^^^^^^^^^^^^^^^^^^^^^
  File "/usr/local/lib/python3.12/site-packages/sqlalchemy/engine/base.py", line 3302, in raw_connection
    return self.pool.connect()
           ^^^^^^^^^^^^^^^^^^^
  File "/usr/local/lib/python3.12/site-packages/sqlalchemy/pool/base.py", line 449, in connect
    return _ConnectionFairy._checkout(self)
           ^^^^^^^^^^^^^^^^^^^^^^^^^^^^^^^^
  File "/usr/local/lib/python3.12/site-packages/sqlalchemy/pool/base.py", line 1263, in _checkout
    fairy = _ConnectionRecord.checkout(pool)
            ^^^^^^^^^^^^^^^^^^^^^^^^^^^^^^^^
  File "/usr/local/lib/python3.12/site-packages/sqlalchemy/pool/base.py", line 712, in checkout
    rec = pool._do_get()
          ^^^^^^^^^^^^^^
  File "/usr/local/lib/python3.12/site-packages/sqlalchemy/pool/impl.py", line 179, in _do_get
    with util.safe_reraise():
         ^^^^^^^^^^^^^^^^^^^
  File "/usr/local/lib/python3.12/site-packages/sqlalchemy/util/langhelpers.py", line 146, in __exit__
    raise exc_value.with_traceback(exc_tb)
  File "/usr/local/lib/python3.12/site-packages/sqlalchemy/pool/impl.py", line 177, in _do_get
    return self._create_connection()
           ^^^^^^^^^^^^^^^^^^^^^^^^^
  File "/usr/local/lib/python3.12/site-packages/sqlalchemy/pool/base.py", line 390, in _create_connection
    return _ConnectionRecord(self)
           ^^^^^^^^^^^^^^^^^^^^^^^
  File "/usr/local/lib/python3.12/site-packages/sqlalchemy/pool/base.py", line 674, in __init__
    self.__connect()
  File "/usr/local/lib/python3.12/site-packages/sqlalchemy/pool/base.py", line 900, in __connect
    with util.safe_reraise():
         ^^^^^^^^^^^^^^^^^^^
  File "/usr/local/lib/python3.12/site-packages/sqlalchemy/util/langhelpers.py", line 146, in __exit__
    raise exc_value.with_traceback(exc_tb)
  File "/usr/local/lib/python3.12/site-packages/sqlalchemy/pool/base.py", line 896, in __connect
    self.dbapi_connection = connection = pool._invoke_creator(self)
                                         ^^^^^^^^^^^^^^^^^^^^^^^^^^
  File "/usr/local/lib/python3.12/site-packages/sqlalchemy/engine/create.py", line 643, in connect
    return dialect.connect(*cargs, **cparams)
           ^^^^^^^^^^^^^^^^^^^^^^^^^^^^^^^^^^
  File "/usr/local/lib/python3.12/site-packages/sqlalchemy/engine/default.py", line 621, in connect
    return self.loaded_dbapi.connect(*cargs, **cparams)
           ^^^^^^^^^^^^^^^^^^^^^^^^^^^^^^^^^^^^^^^^^^^^
  File "/usr/local/lib/python3.12/site-packages/psycopg2/__init__.py", line 122, in connect
    conn = _connect(dsn, connection_factory=connection_factory, **kwasync)
           ^^^^^^^^^^^^^^^^^^^^^^^^^^^^^^^^^^^^^^^^^^^^^^^^^^^^^^^^^^^^^^^
sqlalchemy.exc.OperationalError: (psycopg2.OperationalError) connection to server at "postgres" (172.18.0.3), port 5432 failed: FATAL:  password authentication failed for user "dt_user"

(Background on this error at: https://sqlalche.me/e/20/e3q8)
2025-10-31 03:35:57,350 - MQTTIngestor - CRITICAL - Database connection failed. Exiting.
2025-10-31 03:35:58,999 - MQTTIngestor - INFO - Starting MQTT Ingestor...
2025-10-31 03:35:59,066 - MQTTIngestor - CRITICAL - Failed to connect to database using SQLAlchemy: (psycopg2.OperationalError) connection to server at "postgres" (172.18.0.3), port 5432 failed: FATAL:  password authentication failed for user "dt_user"

(Background on this error at: https://sqlalche.me/e/20/e3q8)
Traceback (most recent call last):
  File "/usr/local/lib/python3.12/site-packages/sqlalchemy/engine/base.py", line 146, in __init__
    self._dbapi_connection = engine.raw_connection()
                             ^^^^^^^^^^^^^^^^^^^^^^^
  File "/usr/local/lib/python3.12/site-packages/sqlalchemy/engine/base.py", line 3302, in raw_connection
    return self.pool.connect()
           ^^^^^^^^^^^^^^^^^^^
  File "/usr/local/lib/python3.12/site-packages/sqlalchemy/pool/base.py", line 449, in connect
    return _ConnectionFairy._checkout(self)
           ^^^^^^^^^^^^^^^^^^^^^^^^^^^^^^^^
  File "/usr/local/lib/python3.12/site-packages/sqlalchemy/pool/base.py", line 1263, in _checkout
    fairy = _ConnectionRecord.checkout(pool)
            ^^^^^^^^^^^^^^^^^^^^^^^^^^^^^^^^
  File "/usr/local/lib/python3.12/site-packages/sqlalchemy/pool/base.py", line 712, in checkout
    rec = pool._do_get()
          ^^^^^^^^^^^^^^
  File "/usr/local/lib/python3.12/site-packages/sqlalchemy/pool/impl.py", line 179, in _do_get
    with util.safe_reraise():
         ^^^^^^^^^^^^^^^^^^^
  File "/usr/local/lib/python3.12/site-packages/sqlalchemy/util/langhelpers.py", line 146, in __exit__
    raise exc_value.with_traceback(exc_tb)
  File "/usr/local/lib/python3.12/site-packages/sqlalchemy/pool/impl.py", line 177, in _do_get
    return self._create_connection()
           ^^^^^^^^^^^^^^^^^^^^^^^^^
  File "/usr/local/lib/python3.12/site-packages/sqlalchemy/pool/base.py", line 390, in _create_connection
    return _ConnectionRecord(self)
           ^^^^^^^^^^^^^^^^^^^^^^^
  File "/usr/local/lib/python3.12/site-packages/sqlalchemy/pool/base.py", line 674, in __init__
    self.__connect()
  File "/usr/local/lib/python3.12/site-packages/sqlalchemy/pool/base.py", line 900, in __connect
    with util.safe_reraise():
         ^^^^^^^^^^^^^^^^^^^
  File "/usr/local/lib/python3.12/site-packages/sqlalchemy/util/langhelpers.py", line 146, in __exit__
    raise exc_value.with_traceback(exc_tb)
  File "/usr/local/lib/python3.12/site-packages/sqlalchemy/pool/base.py", line 896, in __connect
    self.dbapi_connection = connection = pool._invoke_creator(self)
                                         ^^^^^^^^^^^^^^^^^^^^^^^^^^
  File "/usr/local/lib/python3.12/site-packages/sqlalchemy/engine/create.py", line 643, in connect
    return dialect.connect(*cargs, **cparams)
           ^^^^^^^^^^^^^^^^^^^^^^^^^^^^^^^^^^
  File "/usr/local/lib/python3.12/site-packages/sqlalchemy/engine/default.py", line 621, in connect
    return self.loaded_dbapi.connect(*cargs, **cparams)
           ^^^^^^^^^^^^^^^^^^^^^^^^^^^^^^^^^^^^^^^^^^^^
  File "/usr/local/lib/python3.12/site-packages/psycopg2/__init__.py", line 122, in connect
    conn = _connect(dsn, connection_factory=connection_factory, **kwasync)
           ^^^^^^^^^^^^^^^^^^^^^^^^^^^^^^^^^^^^^^^^^^^^^^^^^^^^^^^^^^^^^^^
psycopg2.OperationalError: connection to server at "postgres" (172.18.0.3), port 5432 failed: FATAL:  password authentication failed for user "dt_user"


The above exception was the direct cause of the following exception:

Traceback (most recent call last):
  File "/app/Digital_Twin/AI_MODULES/mqtt_ingestor.py", line 127, in init_database_connection
    with db_engine.connect():
         ^^^^^^^^^^^^^^^^^^^
  File "/usr/local/lib/python3.12/site-packages/sqlalchemy/engine/base.py", line 3278, in connect
    return self._connection_cls(self)
           ^^^^^^^^^^^^^^^^^^^^^^^^^^
  File "/usr/local/lib/python3.12/site-packages/sqlalchemy/engine/base.py", line 148, in __init__
    Connection._handle_dbapi_exception_noconnection(
  File "/usr/local/lib/python3.12/site-packages/sqlalchemy/engine/base.py", line 2442, in _handle_dbapi_exception_noconnection
    raise sqlalchemy_exception.with_traceback(exc_info[2]) from e
  File "/usr/local/lib/python3.12/site-packages/sqlalchemy/engine/base.py", line 146, in __init__
    self._dbapi_connection = engine.raw_connection()
                             ^^^^^^^^^^^^^^^^^^^^^^^
  File "/usr/local/lib/python3.12/site-packages/sqlalchemy/engine/base.py", line 3302, in raw_connection
    return self.pool.connect()
           ^^^^^^^^^^^^^^^^^^^
  File "/usr/local/lib/python3.12/site-packages/sqlalchemy/pool/base.py", line 449, in connect
    return _ConnectionFairy._checkout(self)
           ^^^^^^^^^^^^^^^^^^^^^^^^^^^^^^^^
  File "/usr/local/lib/python3.12/site-packages/sqlalchemy/pool/base.py", line 1263, in _checkout
    fairy = _ConnectionRecord.checkout(pool)
            ^^^^^^^^^^^^^^^^^^^^^^^^^^^^^^^^
  File "/usr/local/lib/python3.12/site-packages/sqlalchemy/pool/base.py", line 712, in checkout
    rec = pool._do_get()
          ^^^^^^^^^^^^^^
  File "/usr/local/lib/python3.12/site-packages/sqlalchemy/pool/impl.py", line 179, in _do_get
    with util.safe_reraise():
         ^^^^^^^^^^^^^^^^^^^
  File "/usr/local/lib/python3.12/site-packages/sqlalchemy/util/langhelpers.py", line 146, in __exit__
    raise exc_value.with_traceback(exc_tb)
  File "/usr/local/lib/python3.12/site-packages/sqlalchemy/pool/impl.py", line 177, in _do_get
    return self._create_connection()
           ^^^^^^^^^^^^^^^^^^^^^^^^^
  File "/usr/local/lib/python3.12/site-packages/sqlalchemy/pool/base.py", line 390, in _create_connection
    return _ConnectionRecord(self)
           ^^^^^^^^^^^^^^^^^^^^^^^
  File "/usr/local/lib/python3.12/site-packages/sqlalchemy/pool/base.py", line 674, in __init__
    self.__connect()
  File "/usr/local/lib/python3.12/site-packages/sqlalchemy/pool/base.py", line 900, in __connect
    with util.safe_reraise():
         ^^^^^^^^^^^^^^^^^^^
  File "/usr/local/lib/python3.12/site-packages/sqlalchemy/util/langhelpers.py", line 146, in __exit__
    raise exc_value.with_traceback(exc_tb)
  File "/usr/local/lib/python3.12/site-packages/sqlalchemy/pool/base.py", line 896, in __connect
    self.dbapi_connection = connection = pool._invoke_creator(self)
                                         ^^^^^^^^^^^^^^^^^^^^^^^^^^
  File "/usr/local/lib/python3.12/site-packages/sqlalchemy/engine/create.py", line 643, in connect
    return dialect.connect(*cargs, **cparams)
           ^^^^^^^^^^^^^^^^^^^^^^^^^^^^^^^^^^
  File "/usr/local/lib/python3.12/site-packages/sqlalchemy/engine/default.py", line 621, in connect
    return self.loaded_dbapi.connect(*cargs, **cparams)
           ^^^^^^^^^^^^^^^^^^^^^^^^^^^^^^^^^^^^^^^^^^^^
  File "/usr/local/lib/python3.12/site-packages/psycopg2/__init__.py", line 122, in connect
    conn = _connect(dsn, connection_factory=connection_factory, **kwasync)
           ^^^^^^^^^^^^^^^^^^^^^^^^^^^^^^^^^^^^^^^^^^^^^^^^^^^^^^^^^^^^^^^
sqlalchemy.exc.OperationalError: (psycopg2.OperationalError) connection to server at "postgres" (172.18.0.3), port 5432 failed: FATAL:  password authentication failed for user "dt_user"

(Background on this error at: https://sqlalche.me/e/20/e3q8)
2025-10-31 03:35:59,096 - MQTTIngestor - CRITICAL - Database connection failed. Exiting.
2025-10-31 03:36:00,795 - MQTTIngestor - INFO - Starting MQTT Ingestor...
2025-10-31 03:36:00,828 - MQTTIngestor - CRITICAL - Failed to connect to database using SQLAlchemy: (psycopg2.OperationalError) connection to server at "postgres" (172.18.0.3), port 5432 failed: FATAL:  password authentication failed for user "dt_user"

(Background on this error at: https://sqlalche.me/e/20/e3q8)
Traceback (most recent call last):
  File "/usr/local/lib/python3.12/site-packages/sqlalchemy/engine/base.py", line 146, in __init__
    self._dbapi_connection = engine.raw_connection()
                             ^^^^^^^^^^^^^^^^^^^^^^^
  File "/usr/local/lib/python3.12/site-packages/sqlalchemy/engine/base.py", line 3302, in raw_connection
    return self.pool.connect()
           ^^^^^^^^^^^^^^^^^^^
  File "/usr/local/lib/python3.12/site-packages/sqlalchemy/pool/base.py", line 449, in connect
    return _ConnectionFairy._checkout(self)
           ^^^^^^^^^^^^^^^^^^^^^^^^^^^^^^^^
  File "/usr/local/lib/python3.12/site-packages/sqlalchemy/pool/base.py", line 1263, in _checkout
    fairy = _ConnectionRecord.checkout(pool)
            ^^^^^^^^^^^^^^^^^^^^^^^^^^^^^^^^
  File "/usr/local/lib/python3.12/site-packages/sqlalchemy/pool/base.py", line 712, in checkout
    rec = pool._do_get()
          ^^^^^^^^^^^^^^
  File "/usr/local/lib/python3.12/site-packages/sqlalchemy/pool/impl.py", line 179, in _do_get
    with util.safe_reraise():
         ^^^^^^^^^^^^^^^^^^^
  File "/usr/local/lib/python3.12/site-packages/sqlalchemy/util/langhelpers.py", line 146, in __exit__
    raise exc_value.with_traceback(exc_tb)
  File "/usr/local/lib/python3.12/site-packages/sqlalchemy/pool/impl.py", line 177, in _do_get
    return self._create_connection()
           ^^^^^^^^^^^^^^^^^^^^^^^^^
  File "/usr/local/lib/python3.12/site-packages/sqlalchemy/pool/base.py", line 390, in _create_connection
    return _ConnectionRecord(self)
           ^^^^^^^^^^^^^^^^^^^^^^^
  File "/usr/local/lib/python3.12/site-packages/sqlalchemy/pool/base.py", line 674, in __init__
    self.__connect()
  File "/usr/local/lib/python3.12/site-packages/sqlalchemy/pool/base.py", line 900, in __connect
    with util.safe_reraise():
         ^^^^^^^^^^^^^^^^^^^
  File "/usr/local/lib/python3.12/site-packages/sqlalchemy/util/langhelpers.py", line 146, in __exit__
    raise exc_value.with_traceback(exc_tb)
  File "/usr/local/lib/python3.12/site-packages/sqlalchemy/pool/base.py", line 896, in __connect
    self.dbapi_connection = connection = pool._invoke_creator(self)
                                         ^^^^^^^^^^^^^^^^^^^^^^^^^^
  File "/usr/local/lib/python3.12/site-packages/sqlalchemy/engine/create.py", line 643, in connect
    return dialect.connect(*cargs, **cparams)
           ^^^^^^^^^^^^^^^^^^^^^^^^^^^^^^^^^^
  File "/usr/local/lib/python3.12/site-packages/sqlalchemy/engine/default.py", line 621, in connect
    return self.loaded_dbapi.connect(*cargs, **cparams)
           ^^^^^^^^^^^^^^^^^^^^^^^^^^^^^^^^^^^^^^^^^^^^
  File "/usr/local/lib/python3.12/site-packages/psycopg2/__init__.py", line 122, in connect
    conn = _connect(dsn, connection_factory=connection_factory, **kwasync)
           ^^^^^^^^^^^^^^^^^^^^^^^^^^^^^^^^^^^^^^^^^^^^^^^^^^^^^^^^^^^^^^^
psycopg2.OperationalError: connection to server at "postgres" (172.18.0.3), port 5432 failed: FATAL:  password authentication failed for user "dt_user"


The above exception was the direct cause of the following exception:

Traceback (most recent call last):
  File "/app/Digital_Twin/AI_MODULES/mqtt_ingestor.py", line 127, in init_database_connection
    with db_engine.connect():
         ^^^^^^^^^^^^^^^^^^^
  File "/usr/local/lib/python3.12/site-packages/sqlalchemy/engine/base.py", line 3278, in connect
    return self._connection_cls(self)
           ^^^^^^^^^^^^^^^^^^^^^^^^^^
  File "/usr/local/lib/python3.12/site-packages/sqlalchemy/engine/base.py", line 148, in __init__
    Connection._handle_dbapi_exception_noconnection(
  File "/usr/local/lib/python3.12/site-packages/sqlalchemy/engine/base.py", line 2442, in _handle_dbapi_exception_noconnection
    raise sqlalchemy_exception.with_traceback(exc_info[2]) from e
  File "/usr/local/lib/python3.12/site-packages/sqlalchemy/engine/base.py", line 146, in __init__
    self._dbapi_connection = engine.raw_connection()
                             ^^^^^^^^^^^^^^^^^^^^^^^
  File "/usr/local/lib/python3.12/site-packages/sqlalchemy/engine/base.py", line 3302, in raw_connection
    return self.pool.connect()
           ^^^^^^^^^^^^^^^^^^^
  File "/usr/local/lib/python3.12/site-packages/sqlalchemy/pool/base.py", line 449, in connect
    return _ConnectionFairy._checkout(self)
           ^^^^^^^^^^^^^^^^^^^^^^^^^^^^^^^^
  File "/usr/local/lib/python3.12/site-packages/sqlalchemy/pool/base.py", line 1263, in _checkout
    fairy = _ConnectionRecord.checkout(pool)
            ^^^^^^^^^^^^^^^^^^^^^^^^^^^^^^^^
  File "/usr/local/lib/python3.12/site-packages/sqlalchemy/pool/base.py", line 712, in checkout
    rec = pool._do_get()
          ^^^^^^^^^^^^^^
  File "/usr/local/lib/python3.12/site-packages/sqlalchemy/pool/impl.py", line 179, in _do_get
    with util.safe_reraise():
         ^^^^^^^^^^^^^^^^^^^
  File "/usr/local/lib/python3.12/site-packages/sqlalchemy/util/langhelpers.py", line 146, in __exit__
    raise exc_value.with_traceback(exc_tb)
  File "/usr/local/lib/python3.12/site-packages/sqlalchemy/pool/impl.py", line 177, in _do_get
    return self._create_connection()
           ^^^^^^^^^^^^^^^^^^^^^^^^^
  File "/usr/local/lib/python3.12/site-packages/sqlalchemy/pool/base.py", line 390, in _create_connection
    return _ConnectionRecord(self)
           ^^^^^^^^^^^^^^^^^^^^^^^
  File "/usr/local/lib/python3.12/site-packages/sqlalchemy/pool/base.py", line 674, in __init__
    self.__connect()
  File "/usr/local/lib/python3.12/site-packages/sqlalchemy/pool/base.py", line 900, in __connect
    with util.safe_reraise():
         ^^^^^^^^^^^^^^^^^^^
  File "/usr/local/lib/python3.12/site-packages/sqlalchemy/util/langhelpers.py", line 146, in __exit__
    raise exc_value.with_traceback(exc_tb)
  File "/usr/local/lib/python3.12/site-packages/sqlalchemy/pool/base.py", line 896, in __connect
    self.dbapi_connection = connection = pool._invoke_creator(self)
                                         ^^^^^^^^^^^^^^^^^^^^^^^^^^
  File "/usr/local/lib/python3.12/site-packages/sqlalchemy/engine/create.py", line 643, in connect
    return dialect.connect(*cargs, **cparams)
           ^^^^^^^^^^^^^^^^^^^^^^^^^^^^^^^^^^
  File "/usr/local/lib/python3.12/site-packages/sqlalchemy/engine/default.py", line 621, in connect
    return self.loaded_dbapi.connect(*cargs, **cparams)
           ^^^^^^^^^^^^^^^^^^^^^^^^^^^^^^^^^^^^^^^^^^^^
  File "/usr/local/lib/python3.12/site-packages/psycopg2/__init__.py", line 122, in connect
    conn = _connect(dsn, connection_factory=connection_factory, **kwasync)
           ^^^^^^^^^^^^^^^^^^^^^^^^^^^^^^^^^^^^^^^^^^^^^^^^^^^^^^^^^^^^^^^
sqlalchemy.exc.OperationalError: (psycopg2.OperationalError) connection to server at "postgres" (172.18.0.3), port 5432 failed: FATAL:  password authentication failed for user "dt_user"

(Background on this error at: https://sqlalche.me/e/20/e3q8)
2025-10-31 03:36:00,833 - MQTTIngestor - CRITICAL - Database connection failed. Exiting.
2025-10-31 03:36:02,889 - MQTTIngestor - INFO - Starting MQTT Ingestor...
2025-10-31 03:36:02,938 - MQTTIngestor - CRITICAL - Failed to connect to database using SQLAlchemy: (psycopg2.OperationalError) connection to server at "postgres" (172.18.0.3), port 5432 failed: FATAL:  password authentication failed for user "dt_user"

(Background on this error at: https://sqlalche.me/e/20/e3q8)
Traceback (most recent call last):
  File "/usr/local/lib/python3.12/site-packages/sqlalchemy/engine/base.py", line 146, in __init__
    self._dbapi_connection = engine.raw_connection()
                             ^^^^^^^^^^^^^^^^^^^^^^^
  File "/usr/local/lib/python3.12/site-packages/sqlalchemy/engine/base.py", line 3302, in raw_connection
    return self.pool.connect()
           ^^^^^^^^^^^^^^^^^^^
  File "/usr/local/lib/python3.12/site-packages/sqlalchemy/pool/base.py", line 449, in connect
    return _ConnectionFairy._checkout(self)
           ^^^^^^^^^^^^^^^^^^^^^^^^^^^^^^^^
  File "/usr/local/lib/python3.12/site-packages/sqlalchemy/pool/base.py", line 1263, in _checkout
    fairy = _ConnectionRecord.checkout(pool)
            ^^^^^^^^^^^^^^^^^^^^^^^^^^^^^^^^
  File "/usr/local/lib/python3.12/site-packages/sqlalchemy/pool/base.py", line 712, in checkout
    rec = pool._do_get()
          ^^^^^^^^^^^^^^
  File "/usr/local/lib/python3.12/site-packages/sqlalchemy/pool/impl.py", line 179, in _do_get
    with util.safe_reraise():
         ^^^^^^^^^^^^^^^^^^^
  File "/usr/local/lib/python3.12/site-packages/sqlalchemy/util/langhelpers.py", line 146, in __exit__
    raise exc_value.with_traceback(exc_tb)
  File "/usr/local/lib/python3.12/site-packages/sqlalchemy/pool/impl.py", line 177, in _do_get
    return self._create_connection()
           ^^^^^^^^^^^^^^^^^^^^^^^^^
  File "/usr/local/lib/python3.12/site-packages/sqlalchemy/pool/base.py", line 390, in _create_connection
    return _ConnectionRecord(self)
           ^^^^^^^^^^^^^^^^^^^^^^^
  File "/usr/local/lib/python3.12/site-packages/sqlalchemy/pool/base.py", line 674, in __init__
    self.__connect()
  File "/usr/local/lib/python3.12/site-packages/sqlalchemy/pool/base.py", line 900, in __connect
    with util.safe_reraise():
         ^^^^^^^^^^^^^^^^^^^
  File "/usr/local/lib/python3.12/site-packages/sqlalchemy/util/langhelpers.py", line 146, in __exit__
    raise exc_value.with_traceback(exc_tb)
  File "/usr/local/lib/python3.12/site-packages/sqlalchemy/pool/base.py", line 896, in __connect
    self.dbapi_connection = connection = pool._invoke_creator(self)
                                         ^^^^^^^^^^^^^^^^^^^^^^^^^^
  File "/usr/local/lib/python3.12/site-packages/sqlalchemy/engine/create.py", line 643, in connect
    return dialect.connect(*cargs, **cparams)
           ^^^^^^^^^^^^^^^^^^^^^^^^^^^^^^^^^^
  File "/usr/local/lib/python3.12/site-packages/sqlalchemy/engine/default.py", line 621, in connect
    return self.loaded_dbapi.connect(*cargs, **cparams)
           ^^^^^^^^^^^^^^^^^^^^^^^^^^^^^^^^^^^^^^^^^^^^
  File "/usr/local/lib/python3.12/site-packages/psycopg2/__init__.py", line 122, in connect
    conn = _connect(dsn, connection_factory=connection_factory, **kwasync)
           ^^^^^^^^^^^^^^^^^^^^^^^^^^^^^^^^^^^^^^^^^^^^^^^^^^^^^^^^^^^^^^^
psycopg2.OperationalError: connection to server at "postgres" (172.18.0.3), port 5432 failed: FATAL:  password authentication failed for user "dt_user"


The above exception was the direct cause of the following exception:

Traceback (most recent call last):
  File "/app/Digital_Twin/AI_MODULES/mqtt_ingestor.py", line 127, in init_database_connection
    with db_engine.connect():
         ^^^^^^^^^^^^^^^^^^^
  File "/usr/local/lib/python3.12/site-packages/sqlalchemy/engine/base.py", line 3278, in connect
    return self._connection_cls(self)
           ^^^^^^^^^^^^^^^^^^^^^^^^^^
  File "/usr/local/lib/python3.12/site-packages/sqlalchemy/engine/base.py", line 148, in __init__
    Connection._handle_dbapi_exception_noconnection(
  File "/usr/local/lib/python3.12/site-packages/sqlalchemy/engine/base.py", line 2442, in _handle_dbapi_exception_noconnection
    raise sqlalchemy_exception.with_traceback(exc_info[2]) from e
  File "/usr/local/lib/python3.12/site-packages/sqlalchemy/engine/base.py", line 146, in __init__
    self._dbapi_connection = engine.raw_connection()
                             ^^^^^^^^^^^^^^^^^^^^^^^
  File "/usr/local/lib/python3.12/site-packages/sqlalchemy/engine/base.py", line 3302, in raw_connection
    return self.pool.connect()
           ^^^^^^^^^^^^^^^^^^^
  File "/usr/local/lib/python3.12/site-packages/sqlalchemy/pool/base.py", line 449, in connect
    return _ConnectionFairy._checkout(self)
           ^^^^^^^^^^^^^^^^^^^^^^^^^^^^^^^^
  File "/usr/local/lib/python3.12/site-packages/sqlalchemy/pool/base.py", line 1263, in _checkout
    fairy = _ConnectionRecord.checkout(pool)
            ^^^^^^^^^^^^^^^^^^^^^^^^^^^^^^^^
  File "/usr/local/lib/python3.12/site-packages/sqlalchemy/pool/base.py", line 712, in checkout
    rec = pool._do_get()
          ^^^^^^^^^^^^^^
  File "/usr/local/lib/python3.12/site-packages/sqlalchemy/pool/impl.py", line 179, in _do_get
    with util.safe_reraise():
         ^^^^^^^^^^^^^^^^^^^
  File "/usr/local/lib/python3.12/site-packages/sqlalchemy/util/langhelpers.py", line 146, in __exit__
    raise exc_value.with_traceback(exc_tb)
  File "/usr/local/lib/python3.12/site-packages/sqlalchemy/pool/impl.py", line 177, in _do_get
    return self._create_connection()
           ^^^^^^^^^^^^^^^^^^^^^^^^^
  File "/usr/local/lib/python3.12/site-packages/sqlalchemy/pool/base.py", line 390, in _create_connection
    return _ConnectionRecord(self)
           ^^^^^^^^^^^^^^^^^^^^^^^
  File "/usr/local/lib/python3.12/site-packages/sqlalchemy/pool/base.py", line 674, in __init__
    self.__connect()
  File "/usr/local/lib/python3.12/site-packages/sqlalchemy/pool/base.py", line 900, in __connect
    with util.safe_reraise():
         ^^^^^^^^^^^^^^^^^^^
  File "/usr/local/lib/python3.12/site-packages/sqlalchemy/util/langhelpers.py", line 146, in __exit__
    raise exc_value.with_traceback(exc_tb)
  File "/usr/local/lib/python3.12/site-packages/sqlalchemy/pool/base.py", line 896, in __connect
    self.dbapi_connection = connection = pool._invoke_creator(self)
                                         ^^^^^^^^^^^^^^^^^^^^^^^^^^
  File "/usr/local/lib/python3.12/site-packages/sqlalchemy/engine/create.py", line 643, in connect
    return dialect.connect(*cargs, **cparams)
           ^^^^^^^^^^^^^^^^^^^^^^^^^^^^^^^^^^
  File "/usr/local/lib/python3.12/site-packages/sqlalchemy/engine/default.py", line 621, in connect
    return self.loaded_dbapi.connect(*cargs, **cparams)
           ^^^^^^^^^^^^^^^^^^^^^^^^^^^^^^^^^^^^^^^^^^^^
  File "/usr/local/lib/python3.12/site-packages/psycopg2/__init__.py", line 122, in connect
    conn = _connect(dsn, connection_factory=connection_factory, **kwasync)
           ^^^^^^^^^^^^^^^^^^^^^^^^^^^^^^^^^^^^^^^^^^^^^^^^^^^^^^^^^^^^^^^
sqlalchemy.exc.OperationalError: (psycopg2.OperationalError) connection to server at "postgres" (172.18.0.3), port 5432 failed: FATAL:  password authentication failed for user "dt_user"

(Background on this error at: https://sqlalche.me/e/20/e3q8)
2025-10-31 03:36:02,945 - MQTTIngestor - CRITICAL - Database connection failed. Exiting.
2025-10-31 03:36:05,642 - MQTTIngestor - INFO - Starting MQTT Ingestor...
2025-10-31 03:36:05,683 - MQTTIngestor - CRITICAL - Failed to connect to database using SQLAlchemy: (psycopg2.OperationalError) connection to server at "postgres" (172.18.0.3), port 5432 failed: FATAL:  password authentication failed for user "dt_user"

(Background on this error at: https://sqlalche.me/e/20/e3q8)
Traceback (most recent call last):
  File "/usr/local/lib/python3.12/site-packages/sqlalchemy/engine/base.py", line 146, in __init__
    self._dbapi_connection = engine.raw_connection()
                             ^^^^^^^^^^^^^^^^^^^^^^^
  File "/usr/local/lib/python3.12/site-packages/sqlalchemy/engine/base.py", line 3302, in raw_connection
    return self.pool.connect()
           ^^^^^^^^^^^^^^^^^^^
  File "/usr/local/lib/python3.12/site-packages/sqlalchemy/pool/base.py", line 449, in connect
    return _ConnectionFairy._checkout(self)
           ^^^^^^^^^^^^^^^^^^^^^^^^^^^^^^^^
  File "/usr/local/lib/python3.12/site-packages/sqlalchemy/pool/base.py", line 1263, in _checkout
    fairy = _ConnectionRecord.checkout(pool)
            ^^^^^^^^^^^^^^^^^^^^^^^^^^^^^^^^
  File "/usr/local/lib/python3.12/site-packages/sqlalchemy/pool/base.py", line 712, in checkout
    rec = pool._do_get()
          ^^^^^^^^^^^^^^
  File "/usr/local/lib/python3.12/site-packages/sqlalchemy/pool/impl.py", line 179, in _do_get
    with util.safe_reraise():
         ^^^^^^^^^^^^^^^^^^^
  File "/usr/local/lib/python3.12/site-packages/sqlalchemy/util/langhelpers.py", line 146, in __exit__
    raise exc_value.with_traceback(exc_tb)
  File "/usr/local/lib/python3.12/site-packages/sqlalchemy/pool/impl.py", line 177, in _do_get
    return self._create_connection()
           ^^^^^^^^^^^^^^^^^^^^^^^^^
  File "/usr/local/lib/python3.12/site-packages/sqlalchemy/pool/base.py", line 390, in _create_connection
    return _ConnectionRecord(self)
           ^^^^^^^^^^^^^^^^^^^^^^^
  File "/usr/local/lib/python3.12/site-packages/sqlalchemy/pool/base.py", line 674, in __init__
    self.__connect()
  File "/usr/local/lib/python3.12/site-packages/sqlalchemy/pool/base.py", line 900, in __connect
    with util.safe_reraise():
         ^^^^^^^^^^^^^^^^^^^
  File "/usr/local/lib/python3.12/site-packages/sqlalchemy/util/langhelpers.py", line 146, in __exit__
    raise exc_value.with_traceback(exc_tb)
  File "/usr/local/lib/python3.12/site-packages/sqlalchemy/pool/base.py", line 896, in __connect
    self.dbapi_connection = connection = pool._invoke_creator(self)
                                         ^^^^^^^^^^^^^^^^^^^^^^^^^^
  File "/usr/local/lib/python3.12/site-packages/sqlalchemy/engine/create.py", line 643, in connect
    return dialect.connect(*cargs, **cparams)
           ^^^^^^^^^^^^^^^^^^^^^^^^^^^^^^^^^^
  File "/usr/local/lib/python3.12/site-packages/sqlalchemy/engine/default.py", line 621, in connect
    return self.loaded_dbapi.connect(*cargs, **cparams)
           ^^^^^^^^^^^^^^^^^^^^^^^^^^^^^^^^^^^^^^^^^^^^
  File "/usr/local/lib/python3.12/site-packages/psycopg2/__init__.py", line 122, in connect
    conn = _connect(dsn, connection_factory=connection_factory, **kwasync)
           ^^^^^^^^^^^^^^^^^^^^^^^^^^^^^^^^^^^^^^^^^^^^^^^^^^^^^^^^^^^^^^^
psycopg2.OperationalError: connection to server at "postgres" (172.18.0.3), port 5432 failed: FATAL:  password authentication failed for user "dt_user"


The above exception was the direct cause of the following exception:

Traceback (most recent call last):
  File "/app/Digital_Twin/AI_MODULES/mqtt_ingestor.py", line 127, in init_database_connection
    with db_engine.connect():
         ^^^^^^^^^^^^^^^^^^^
  File "/usr/local/lib/python3.12/site-packages/sqlalchemy/engine/base.py", line 3278, in connect
    return self._connection_cls(self)
           ^^^^^^^^^^^^^^^^^^^^^^^^^^
  File "/usr/local/lib/python3.12/site-packages/sqlalchemy/engine/base.py", line 148, in __init__
    Connection._handle_dbapi_exception_noconnection(
  File "/usr/local/lib/python3.12/site-packages/sqlalchemy/engine/base.py", line 2442, in _handle_dbapi_exception_noconnection
    raise sqlalchemy_exception.with_traceback(exc_info[2]) from e
  File "/usr/local/lib/python3.12/site-packages/sqlalchemy/engine/base.py", line 146, in __init__
    self._dbapi_connection = engine.raw_connection()
                             ^^^^^^^^^^^^^^^^^^^^^^^
  File "/usr/local/lib/python3.12/site-packages/sqlalchemy/engine/base.py", line 3302, in raw_connection
    return self.pool.connect()
           ^^^^^^^^^^^^^^^^^^^
  File "/usr/local/lib/python3.12/site-packages/sqlalchemy/pool/base.py", line 449, in connect
    return _ConnectionFairy._checkout(self)
           ^^^^^^^^^^^^^^^^^^^^^^^^^^^^^^^^
  File "/usr/local/lib/python3.12/site-packages/sqlalchemy/pool/base.py", line 1263, in _checkout
    fairy = _ConnectionRecord.checkout(pool)
            ^^^^^^^^^^^^^^^^^^^^^^^^^^^^^^^^
  File "/usr/local/lib/python3.12/site-packages/sqlalchemy/pool/base.py", line 712, in checkout
    rec = pool._do_get()
          ^^^^^^^^^^^^^^
  File "/usr/local/lib/python3.12/site-packages/sqlalchemy/pool/impl.py", line 179, in _do_get
    with util.safe_reraise():
         ^^^^^^^^^^^^^^^^^^^
  File "/usr/local/lib/python3.12/site-packages/sqlalchemy/util/langhelpers.py", line 146, in __exit__
    raise exc_value.with_traceback(exc_tb)
  File "/usr/local/lib/python3.12/site-packages/sqlalchemy/pool/impl.py", line 177, in _do_get
    return self._create_connection()
           ^^^^^^^^^^^^^^^^^^^^^^^^^
  File "/usr/local/lib/python3.12/site-packages/sqlalchemy/pool/base.py", line 390, in _create_connection
    return _ConnectionRecord(self)
           ^^^^^^^^^^^^^^^^^^^^^^^
  File "/usr/local/lib/python3.12/site-packages/sqlalchemy/pool/base.py", line 674, in __init__
    self.__connect()
  File "/usr/local/lib/python3.12/site-packages/sqlalchemy/pool/base.py", line 900, in __connect
    with util.safe_reraise():
         ^^^^^^^^^^^^^^^^^^^
  File "/usr/local/lib/python3.12/site-packages/sqlalchemy/util/langhelpers.py", line 146, in __exit__
    raise exc_value.with_traceback(exc_tb)
  File "/usr/local/lib/python3.12/site-packages/sqlalchemy/pool/base.py", line 896, in __connect
    self.dbapi_connection = connection = pool._invoke_creator(self)
                                         ^^^^^^^^^^^^^^^^^^^^^^^^^^
  File "/usr/local/lib/python3.12/site-packages/sqlalchemy/engine/create.py", line 643, in connect
    return dialect.connect(*cargs, **cparams)
           ^^^^^^^^^^^^^^^^^^^^^^^^^^^^^^^^^^
  File "/usr/local/lib/python3.12/site-packages/sqlalchemy/engine/default.py", line 621, in connect
    return self.loaded_dbapi.connect(*cargs, **cparams)
           ^^^^^^^^^^^^^^^^^^^^^^^^^^^^^^^^^^^^^^^^^^^^
  File "/usr/local/lib/python3.12/site-packages/psycopg2/__init__.py", line 122, in connect
    conn = _connect(dsn, connection_factory=connection_factory, **kwasync)
           ^^^^^^^^^^^^^^^^^^^^^^^^^^^^^^^^^^^^^^^^^^^^^^^^^^^^^^^^^^^^^^^
sqlalchemy.exc.OperationalError: (psycopg2.OperationalError) connection to server at "postgres" (172.18.0.3), port 5432 failed: FATAL:  password authentication failed for user "dt_user"

(Background on this error at: https://sqlalche.me/e/20/e3q8)
2025-10-31 03:36:05,688 - MQTTIngestor - CRITICAL - Database connection failed. Exiting.
2025-10-31 03:36:10,049 - MQTTIngestor - INFO - Starting MQTT Ingestor...
2025-10-31 03:36:10,117 - MQTTIngestor - CRITICAL - Failed to connect to database using SQLAlchemy: (psycopg2.OperationalError) connection to server at "postgres" (172.18.0.3), port 5432 failed: FATAL:  password authentication failed for user "dt_user"

(Background on this error at: https://sqlalche.me/e/20/e3q8)
Traceback (most recent call last):
  File "/usr/local/lib/python3.12/site-packages/sqlalchemy/engine/base.py", line 146, in __init__
    self._dbapi_connection = engine.raw_connection()
                             ^^^^^^^^^^^^^^^^^^^^^^^
  File "/usr/local/lib/python3.12/site-packages/sqlalchemy/engine/base.py", line 3302, in raw_connection
    return self.pool.connect()
           ^^^^^^^^^^^^^^^^^^^
  File "/usr/local/lib/python3.12/site-packages/sqlalchemy/pool/base.py", line 449, in connect
    return _ConnectionFairy._checkout(self)
           ^^^^^^^^^^^^^^^^^^^^^^^^^^^^^^^^
  File "/usr/local/lib/python3.12/site-packages/sqlalchemy/pool/base.py", line 1263, in _checkout
    fairy = _ConnectionRecord.checkout(pool)
            ^^^^^^^^^^^^^^^^^^^^^^^^^^^^^^^^
  File "/usr/local/lib/python3.12/site-packages/sqlalchemy/pool/base.py", line 712, in checkout
    rec = pool._do_get()
          ^^^^^^^^^^^^^^
  File "/usr/local/lib/python3.12/site-packages/sqlalchemy/pool/impl.py", line 179, in _do_get
    with util.safe_reraise():
         ^^^^^^^^^^^^^^^^^^^
  File "/usr/local/lib/python3.12/site-packages/sqlalchemy/util/langhelpers.py", line 146, in __exit__
    raise exc_value.with_traceback(exc_tb)
  File "/usr/local/lib/python3.12/site-packages/sqlalchemy/pool/impl.py", line 177, in _do_get
    return self._create_connection()
           ^^^^^^^^^^^^^^^^^^^^^^^^^
  File "/usr/local/lib/python3.12/site-packages/sqlalchemy/pool/base.py", line 390, in _create_connection
    return _ConnectionRecord(self)
           ^^^^^^^^^^^^^^^^^^^^^^^
  File "/usr/local/lib/python3.12/site-packages/sqlalchemy/pool/base.py", line 674, in __init__
    self.__connect()
  File "/usr/local/lib/python3.12/site-packages/sqlalchemy/pool/base.py", line 900, in __connect
    with util.safe_reraise():
         ^^^^^^^^^^^^^^^^^^^
  File "/usr/local/lib/python3.12/site-packages/sqlalchemy/util/langhelpers.py", line 146, in __exit__
    raise exc_value.with_traceback(exc_tb)
  File "/usr/local/lib/python3.12/site-packages/sqlalchemy/pool/base.py", line 896, in __connect
    self.dbapi_connection = connection = pool._invoke_creator(self)
                                         ^^^^^^^^^^^^^^^^^^^^^^^^^^
  File "/usr/local/lib/python3.12/site-packages/sqlalchemy/engine/create.py", line 643, in connect
    return dialect.connect(*cargs, **cparams)
           ^^^^^^^^^^^^^^^^^^^^^^^^^^^^^^^^^^
  File "/usr/local/lib/python3.12/site-packages/sqlalchemy/engine/default.py", line 621, in connect
    return self.loaded_dbapi.connect(*cargs, **cparams)
           ^^^^^^^^^^^^^^^^^^^^^^^^^^^^^^^^^^^^^^^^^^^^
  File "/usr/local/lib/python3.12/site-packages/psycopg2/__init__.py", line 122, in connect
    conn = _connect(dsn, connection_factory=connection_factory, **kwasync)
           ^^^^^^^^^^^^^^^^^^^^^^^^^^^^^^^^^^^^^^^^^^^^^^^^^^^^^^^^^^^^^^^
psycopg2.OperationalError: connection to server at "postgres" (172.18.0.3), port 5432 failed: FATAL:  password authentication failed for user "dt_user"


The above exception was the direct cause of the following exception:

Traceback (most recent call last):
  File "/app/Digital_Twin/AI_MODULES/mqtt_ingestor.py", line 127, in init_database_connection
    with db_engine.connect():
         ^^^^^^^^^^^^^^^^^^^
  File "/usr/local/lib/python3.12/site-packages/sqlalchemy/engine/base.py", line 3278, in connect
    return self._connection_cls(self)
           ^^^^^^^^^^^^^^^^^^^^^^^^^^
  File "/usr/local/lib/python3.12/site-packages/sqlalchemy/engine/base.py", line 148, in __init__
    Connection._handle_dbapi_exception_noconnection(
  File "/usr/local/lib/python3.12/site-packages/sqlalchemy/engine/base.py", line 2442, in _handle_dbapi_exception_noconnection
    raise sqlalchemy_exception.with_traceback(exc_info[2]) from e
  File "/usr/local/lib/python3.12/site-packages/sqlalchemy/engine/base.py", line 146, in __init__
    self._dbapi_connection = engine.raw_connection()
                             ^^^^^^^^^^^^^^^^^^^^^^^
  File "/usr/local/lib/python3.12/site-packages/sqlalchemy/engine/base.py", line 3302, in raw_connection
    return self.pool.connect()
           ^^^^^^^^^^^^^^^^^^^
  File "/usr/local/lib/python3.12/site-packages/sqlalchemy/pool/base.py", line 449, in connect
    return _ConnectionFairy._checkout(self)
           ^^^^^^^^^^^^^^^^^^^^^^^^^^^^^^^^
  File "/usr/local/lib/python3.12/site-packages/sqlalchemy/pool/base.py", line 1263, in _checkout
    fairy = _ConnectionRecord.checkout(pool)
            ^^^^^^^^^^^^^^^^^^^^^^^^^^^^^^^^
  File "/usr/local/lib/python3.12/site-packages/sqlalchemy/pool/base.py", line 712, in checkout
    rec = pool._do_get()
          ^^^^^^^^^^^^^^
  File "/usr/local/lib/python3.12/site-packages/sqlalchemy/pool/impl.py", line 179, in _do_get
    with util.safe_reraise():
         ^^^^^^^^^^^^^^^^^^^
  File "/usr/local/lib/python3.12/site-packages/sqlalchemy/util/langhelpers.py", line 146, in __exit__
    raise exc_value.with_traceback(exc_tb)
  File "/usr/local/lib/python3.12/site-packages/sqlalchemy/pool/impl.py", line 177, in _do_get
    return self._create_connection()
           ^^^^^^^^^^^^^^^^^^^^^^^^^
  File "/usr/local/lib/python3.12/site-packages/sqlalchemy/pool/base.py", line 390, in _create_connection
    return _ConnectionRecord(self)
           ^^^^^^^^^^^^^^^^^^^^^^^
  File "/usr/local/lib/python3.12/site-packages/sqlalchemy/pool/base.py", line 674, in __init__
    self.__connect()
  File "/usr/local/lib/python3.12/site-packages/sqlalchemy/pool/base.py", line 900, in __connect
    with util.safe_reraise():
         ^^^^^^^^^^^^^^^^^^^
  File "/usr/local/lib/python3.12/site-packages/sqlalchemy/util/langhelpers.py", line 146, in __exit__
    raise exc_value.with_traceback(exc_tb)
  File "/usr/local/lib/python3.12/site-packages/sqlalchemy/pool/base.py", line 896, in __connect
    self.dbapi_connection = connection = pool._invoke_creator(self)
                                         ^^^^^^^^^^^^^^^^^^^^^^^^^^
  File "/usr/local/lib/python3.12/site-packages/sqlalchemy/engine/create.py", line 643, in connect
    return dialect.connect(*cargs, **cparams)
           ^^^^^^^^^^^^^^^^^^^^^^^^^^^^^^^^^^
  File "/usr/local/lib/python3.12/site-packages/sqlalchemy/engine/default.py", line 621, in connect
    return self.loaded_dbapi.connect(*cargs, **cparams)
           ^^^^^^^^^^^^^^^^^^^^^^^^^^^^^^^^^^^^^^^^^^^^
  File "/usr/local/lib/python3.12/site-packages/psycopg2/__init__.py", line 122, in connect
    conn = _connect(dsn, connection_factory=connection_factory, **kwasync)
           ^^^^^^^^^^^^^^^^^^^^^^^^^^^^^^^^^^^^^^^^^^^^^^^^^^^^^^^^^^^^^^^
sqlalchemy.exc.OperationalError: (psycopg2.OperationalError) connection to server at "postgres" (172.18.0.3), port 5432 failed: FATAL:  password authentication failed for user "dt_user"

(Background on this error at: https://sqlalche.me/e/20/e3q8)
2025-10-31 03:36:10,135 - MQTTIngestor - CRITICAL - Database connection failed. Exiting.
2025-10-31 03:36:18,300 - MQTTIngestor - INFO - Starting MQTT Ingestor...
2025-10-31 03:36:18,359 - MQTTIngestor - CRITICAL - Failed to connect to database using SQLAlchemy: (psycopg2.OperationalError) connection to server at "postgres" (172.18.0.3), port 5432 failed: FATAL:  password authentication failed for user "dt_user"

(Background on this error at: https://sqlalche.me/e/20/e3q8)
Traceback (most recent call last):
  File "/usr/local/lib/python3.12/site-packages/sqlalchemy/engine/base.py", line 146, in __init__
    self._dbapi_connection = engine.raw_connection()
                             ^^^^^^^^^^^^^^^^^^^^^^^
  File "/usr/local/lib/python3.12/site-packages/sqlalchemy/engine/base.py", line 3302, in raw_connection
    return self.pool.connect()
           ^^^^^^^^^^^^^^^^^^^
  File "/usr/local/lib/python3.12/site-packages/sqlalchemy/pool/base.py", line 449, in connect
    return _ConnectionFairy._checkout(self)
           ^^^^^^^^^^^^^^^^^^^^^^^^^^^^^^^^
  File "/usr/local/lib/python3.12/site-packages/sqlalchemy/pool/base.py", line 1263, in _checkout
    fairy = _ConnectionRecord.checkout(pool)
            ^^^^^^^^^^^^^^^^^^^^^^^^^^^^^^^^
  File "/usr/local/lib/python3.12/site-packages/sqlalchemy/pool/base.py", line 712, in checkout
    rec = pool._do_get()
          ^^^^^^^^^^^^^^
  File "/usr/local/lib/python3.12/site-packages/sqlalchemy/pool/impl.py", line 179, in _do_get
    with util.safe_reraise():
         ^^^^^^^^^^^^^^^^^^^
  File "/usr/local/lib/python3.12/site-packages/sqlalchemy/util/langhelpers.py", line 146, in __exit__
    raise exc_value.with_traceback(exc_tb)
  File "/usr/local/lib/python3.12/site-packages/sqlalchemy/pool/impl.py", line 177, in _do_get
    return self._create_connection()
           ^^^^^^^^^^^^^^^^^^^^^^^^^
  File "/usr/local/lib/python3.12/site-packages/sqlalchemy/pool/base.py", line 390, in _create_connection
    return _ConnectionRecord(self)
           ^^^^^^^^^^^^^^^^^^^^^^^
  File "/usr/local/lib/python3.12/site-packages/sqlalchemy/pool/base.py", line 674, in __init__
    self.__connect()
  File "/usr/local/lib/python3.12/site-packages/sqlalchemy/pool/base.py", line 900, in __connect
    with util.safe_reraise():
         ^^^^^^^^^^^^^^^^^^^
  File "/usr/local/lib/python3.12/site-packages/sqlalchemy/util/langhelpers.py", line 146, in __exit__
    raise exc_value.with_traceback(exc_tb)
  File "/usr/local/lib/python3.12/site-packages/sqlalchemy/pool/base.py", line 896, in __connect
    self.dbapi_connection = connection = pool._invoke_creator(self)
                                         ^^^^^^^^^^^^^^^^^^^^^^^^^^
  File "/usr/local/lib/python3.12/site-packages/sqlalchemy/engine/create.py", line 643, in connect
    return dialect.connect(*cargs, **cparams)
           ^^^^^^^^^^^^^^^^^^^^^^^^^^^^^^^^^^
  File "/usr/local/lib/python3.12/site-packages/sqlalchemy/engine/default.py", line 621, in connect
    return self.loaded_dbapi.connect(*cargs, **cparams)
           ^^^^^^^^^^^^^^^^^^^^^^^^^^^^^^^^^^^^^^^^^^^^
  File "/usr/local/lib/python3.12/site-packages/psycopg2/__init__.py", line 122, in connect
    conn = _connect(dsn, connection_factory=connection_factory, **kwasync)
           ^^^^^^^^^^^^^^^^^^^^^^^^^^^^^^^^^^^^^^^^^^^^^^^^^^^^^^^^^^^^^^^
psycopg2.OperationalError: connection to server at "postgres" (172.18.0.3), port 5432 failed: FATAL:  password authentication failed for user "dt_user"


The above exception was the direct cause of the following exception:

Traceback (most recent call last):
  File "/app/Digital_Twin/AI_MODULES/mqtt_ingestor.py", line 127, in init_database_connection
    with db_engine.connect():
         ^^^^^^^^^^^^^^^^^^^
  File "/usr/local/lib/python3.12/site-packages/sqlalchemy/engine/base.py", line 3278, in connect
    return self._connection_cls(self)
           ^^^^^^^^^^^^^^^^^^^^^^^^^^
  File "/usr/local/lib/python3.12/site-packages/sqlalchemy/engine/base.py", line 148, in __init__
    Connection._handle_dbapi_exception_noconnection(
  File "/usr/local/lib/python3.12/site-packages/sqlalchemy/engine/base.py", line 2442, in _handle_dbapi_exception_noconnection
    raise sqlalchemy_exception.with_traceback(exc_info[2]) from e
  File "/usr/local/lib/python3.12/site-packages/sqlalchemy/engine/base.py", line 146, in __init__
    self._dbapi_connection = engine.raw_connection()
                             ^^^^^^^^^^^^^^^^^^^^^^^
  File "/usr/local/lib/python3.12/site-packages/sqlalchemy/engine/base.py", line 3302, in raw_connection
    return self.pool.connect()
           ^^^^^^^^^^^^^^^^^^^
  File "/usr/local/lib/python3.12/site-packages/sqlalchemy/pool/base.py", line 449, in connect
    return _ConnectionFairy._checkout(self)
           ^^^^^^^^^^^^^^^^^^^^^^^^^^^^^^^^
  File "/usr/local/lib/python3.12/site-packages/sqlalchemy/pool/base.py", line 1263, in _checkout
    fairy = _ConnectionRecord.checkout(pool)
            ^^^^^^^^^^^^^^^^^^^^^^^^^^^^^^^^
  File "/usr/local/lib/python3.12/site-packages/sqlalchemy/pool/base.py", line 712, in checkout
    rec = pool._do_get()
          ^^^^^^^^^^^^^^
  File "/usr/local/lib/python3.12/site-packages/sqlalchemy/pool/impl.py", line 179, in _do_get
    with util.safe_reraise():
         ^^^^^^^^^^^^^^^^^^^
  File "/usr/local/lib/python3.12/site-packages/sqlalchemy/util/langhelpers.py", line 146, in __exit__
    raise exc_value.with_traceback(exc_tb)
  File "/usr/local/lib/python3.12/site-packages/sqlalchemy/pool/impl.py", line 177, in _do_get
    return self._create_connection()
           ^^^^^^^^^^^^^^^^^^^^^^^^^
  File "/usr/local/lib/python3.12/site-packages/sqlalchemy/pool/base.py", line 390, in _create_connection
    return _ConnectionRecord(self)
           ^^^^^^^^^^^^^^^^^^^^^^^
  File "/usr/local/lib/python3.12/site-packages/sqlalchemy/pool/base.py", line 674, in __init__
    self.__connect()
  File "/usr/local/lib/python3.12/site-packages/sqlalchemy/pool/base.py", line 900, in __connect
    with util.safe_reraise():
         ^^^^^^^^^^^^^^^^^^^
  File "/usr/local/lib/python3.12/site-packages/sqlalchemy/util/langhelpers.py", line 146, in __exit__
    raise exc_value.with_traceback(exc_tb)
  File "/usr/local/lib/python3.12/site-packages/sqlalchemy/pool/base.py", line 896, in __connect
    self.dbapi_connection = connection = pool._invoke_creator(self)
                                         ^^^^^^^^^^^^^^^^^^^^^^^^^^
  File "/usr/local/lib/python3.12/site-packages/sqlalchemy/engine/create.py", line 643, in connect
    return dialect.connect(*cargs, **cparams)
           ^^^^^^^^^^^^^^^^^^^^^^^^^^^^^^^^^^
  File "/usr/local/lib/python3.12/site-packages/sqlalchemy/engine/default.py", line 621, in connect
    return self.loaded_dbapi.connect(*cargs, **cparams)
           ^^^^^^^^^^^^^^^^^^^^^^^^^^^^^^^^^^^^^^^^^^^^
  File "/usr/local/lib/python3.12/site-packages/psycopg2/__init__.py", line 122, in connect
    conn = _connect(dsn, connection_factory=connection_factory, **kwasync)
           ^^^^^^^^^^^^^^^^^^^^^^^^^^^^^^^^^^^^^^^^^^^^^^^^^^^^^^^^^^^^^^^
sqlalchemy.exc.OperationalError: (psycopg2.OperationalError) connection to server at "postgres" (172.18.0.3), port 5432 failed: FATAL:  password authentication failed for user "dt_user"

(Background on this error at: https://sqlalche.me/e/20/e3q8)
2025-10-31 03:36:18,364 - MQTTIngestor - CRITICAL - Database connection failed. Exiting.
2025-10-31 03:36:32,488 - MQTTIngestor - INFO - Starting MQTT Ingestor...
2025-10-31 03:36:32,545 - MQTTIngestor - CRITICAL - Failed to connect to database using SQLAlchemy: (psycopg2.OperationalError) connection to server at "postgres" (172.18.0.3), port 5432 failed: FATAL:  password authentication failed for user "dt_user"

(Background on this error at: https://sqlalche.me/e/20/e3q8)
Traceback (most recent call last):
  File "/usr/local/lib/python3.12/site-packages/sqlalchemy/engine/base.py", line 146, in __init__
    self._dbapi_connection = engine.raw_connection()
                             ^^^^^^^^^^^^^^^^^^^^^^^
  File "/usr/local/lib/python3.12/site-packages/sqlalchemy/engine/base.py", line 3302, in raw_connection
    return self.pool.connect()
           ^^^^^^^^^^^^^^^^^^^
  File "/usr/local/lib/python3.12/site-packages/sqlalchemy/pool/base.py", line 449, in connect
    return _ConnectionFairy._checkout(self)
           ^^^^^^^^^^^^^^^^^^^^^^^^^^^^^^^^
  File "/usr/local/lib/python3.12/site-packages/sqlalchemy/pool/base.py", line 1263, in _checkout
    fairy = _ConnectionRecord.checkout(pool)
            ^^^^^^^^^^^^^^^^^^^^^^^^^^^^^^^^
  File "/usr/local/lib/python3.12/site-packages/sqlalchemy/pool/base.py", line 712, in checkout
    rec = pool._do_get()
          ^^^^^^^^^^^^^^
  File "/usr/local/lib/python3.12/site-packages/sqlalchemy/pool/impl.py", line 179, in _do_get
    with util.safe_reraise():
         ^^^^^^^^^^^^^^^^^^^
  File "/usr/local/lib/python3.12/site-packages/sqlalchemy/util/langhelpers.py", line 146, in __exit__
    raise exc_value.with_traceback(exc_tb)
  File "/usr/local/lib/python3.12/site-packages/sqlalchemy/pool/impl.py", line 177, in _do_get
    return self._create_connection()
           ^^^^^^^^^^^^^^^^^^^^^^^^^
  File "/usr/local/lib/python3.12/site-packages/sqlalchemy/pool/base.py", line 390, in _create_connection
    return _ConnectionRecord(self)
           ^^^^^^^^^^^^^^^^^^^^^^^
  File "/usr/local/lib/python3.12/site-packages/sqlalchemy/pool/base.py", line 674, in __init__
    self.__connect()
  File "/usr/local/lib/python3.12/site-packages/sqlalchemy/pool/base.py", line 900, in __connect
    with util.safe_reraise():
         ^^^^^^^^^^^^^^^^^^^
  File "/usr/local/lib/python3.12/site-packages/sqlalchemy/util/langhelpers.py", line 146, in __exit__
    raise exc_value.with_traceback(exc_tb)
  File "/usr/local/lib/python3.12/site-packages/sqlalchemy/pool/base.py", line 896, in __connect
    self.dbapi_connection = connection = pool._invoke_creator(self)
                                         ^^^^^^^^^^^^^^^^^^^^^^^^^^
  File "/usr/local/lib/python3.12/site-packages/sqlalchemy/engine/create.py", line 643, in connect
    return dialect.connect(*cargs, **cparams)
           ^^^^^^^^^^^^^^^^^^^^^^^^^^^^^^^^^^
  File "/usr/local/lib/python3.12/site-packages/sqlalchemy/engine/default.py", line 621, in connect
    return self.loaded_dbapi.connect(*cargs, **cparams)
           ^^^^^^^^^^^^^^^^^^^^^^^^^^^^^^^^^^^^^^^^^^^^
  File "/usr/local/lib/python3.12/site-packages/psycopg2/__init__.py", line 122, in connect
    conn = _connect(dsn, connection_factory=connection_factory, **kwasync)
           ^^^^^^^^^^^^^^^^^^^^^^^^^^^^^^^^^^^^^^^^^^^^^^^^^^^^^^^^^^^^^^^
psycopg2.OperationalError: connection to server at "postgres" (172.18.0.3), port 5432 failed: FATAL:  password authentication failed for user "dt_user"


The above exception was the direct cause of the following exception:

Traceback (most recent call last):
  File "/app/Digital_Twin/AI_MODULES/mqtt_ingestor.py", line 127, in init_database_connection
    with db_engine.connect():
         ^^^^^^^^^^^^^^^^^^^
  File "/usr/local/lib/python3.12/site-packages/sqlalchemy/engine/base.py", line 3278, in connect
    return self._connection_cls(self)
           ^^^^^^^^^^^^^^^^^^^^^^^^^^
  File "/usr/local/lib/python3.12/site-packages/sqlalchemy/engine/base.py", line 148, in __init__
    Connection._handle_dbapi_exception_noconnection(
  File "/usr/local/lib/python3.12/site-packages/sqlalchemy/engine/base.py", line 2442, in _handle_dbapi_exception_noconnection
    raise sqlalchemy_exception.with_traceback(exc_info[2]) from e
  File "/usr/local/lib/python3.12/site-packages/sqlalchemy/engine/base.py", line 146, in __init__
    self._dbapi_connection = engine.raw_connection()
                             ^^^^^^^^^^^^^^^^^^^^^^^
  File "/usr/local/lib/python3.12/site-packages/sqlalchemy/engine/base.py", line 3302, in raw_connection
    return self.pool.connect()
           ^^^^^^^^^^^^^^^^^^^
  File "/usr/local/lib/python3.12/site-packages/sqlalchemy/pool/base.py", line 449, in connect
    return _ConnectionFairy._checkout(self)
           ^^^^^^^^^^^^^^^^^^^^^^^^^^^^^^^^
  File "/usr/local/lib/python3.12/site-packages/sqlalchemy/pool/base.py", line 1263, in _checkout
    fairy = _ConnectionRecord.checkout(pool)
            ^^^^^^^^^^^^^^^^^^^^^^^^^^^^^^^^
  File "/usr/local/lib/python3.12/site-packages/sqlalchemy/pool/base.py", line 712, in checkout
    rec = pool._do_get()
          ^^^^^^^^^^^^^^
  File "/usr/local/lib/python3.12/site-packages/sqlalchemy/pool/impl.py", line 179, in _do_get
    with util.safe_reraise():
         ^^^^^^^^^^^^^^^^^^^
  File "/usr/local/lib/python3.12/site-packages/sqlalchemy/util/langhelpers.py", line 146, in __exit__
    raise exc_value.with_traceback(exc_tb)
  File "/usr/local/lib/python3.12/site-packages/sqlalchemy/pool/impl.py", line 177, in _do_get
    return self._create_connection()
           ^^^^^^^^^^^^^^^^^^^^^^^^^
  File "/usr/local/lib/python3.12/site-packages/sqlalchemy/pool/base.py", line 390, in _create_connection
    return _ConnectionRecord(self)
           ^^^^^^^^^^^^^^^^^^^^^^^
  File "/usr/local/lib/python3.12/site-packages/sqlalchemy/pool/base.py", line 674, in __init__
    self.__connect()
  File "/usr/local/lib/python3.12/site-packages/sqlalchemy/pool/base.py", line 900, in __connect
    with util.safe_reraise():
         ^^^^^^^^^^^^^^^^^^^
  File "/usr/local/lib/python3.12/site-packages/sqlalchemy/util/langhelpers.py", line 146, in __exit__
    raise exc_value.with_traceback(exc_tb)
  File "/usr/local/lib/python3.12/site-packages/sqlalchemy/pool/base.py", line 896, in __connect
    self.dbapi_connection = connection = pool._invoke_creator(self)
                                         ^^^^^^^^^^^^^^^^^^^^^^^^^^
  File "/usr/local/lib/python3.12/site-packages/sqlalchemy/engine/create.py", line 643, in connect
    return dialect.connect(*cargs, **cparams)
           ^^^^^^^^^^^^^^^^^^^^^^^^^^^^^^^^^^
  File "/usr/local/lib/python3.12/site-packages/sqlalchemy/engine/default.py", line 621, in connect
    return self.loaded_dbapi.connect(*cargs, **cparams)
           ^^^^^^^^^^^^^^^^^^^^^^^^^^^^^^^^^^^^^^^^^^^^
  File "/usr/local/lib/python3.12/site-packages/psycopg2/__init__.py", line 122, in connect
    conn = _connect(dsn, connection_factory=connection_factory, **kwasync)
           ^^^^^^^^^^^^^^^^^^^^^^^^^^^^^^^^^^^^^^^^^^^^^^^^^^^^^^^^^^^^^^^
sqlalchemy.exc.OperationalError: (psycopg2.OperationalError) connection to server at "postgres" (172.18.0.3), port 5432 failed: FATAL:  password authentication failed for user "dt_user"

(Background on this error at: https://sqlalche.me/e/20/e3q8)
2025-10-31 03:36:32,550 - MQTTIngestor - CRITICAL - Database connection failed. Exiting.
2025-10-31 03:36:59,474 - MQTTIngestor - INFO - Starting MQTT Ingestor...
2025-10-31 03:36:59,525 - MQTTIngestor - CRITICAL - Failed to connect to database using SQLAlchemy: (psycopg2.OperationalError) connection to server at "postgres" (172.18.0.3), port 5432 failed: FATAL:  password authentication failed for user "dt_user"

(Background on this error at: https://sqlalche.me/e/20/e3q8)
Traceback (most recent call last):
  File "/usr/local/lib/python3.12/site-packages/sqlalchemy/engine/base.py", line 146, in __init__
    self._dbapi_connection = engine.raw_connection()
                             ^^^^^^^^^^^^^^^^^^^^^^^
  File "/usr/local/lib/python3.12/site-packages/sqlalchemy/engine/base.py", line 3302, in raw_connection
    return self.pool.connect()
           ^^^^^^^^^^^^^^^^^^^
  File "/usr/local/lib/python3.12/site-packages/sqlalchemy/pool/base.py", line 449, in connect
    return _ConnectionFairy._checkout(self)
           ^^^^^^^^^^^^^^^^^^^^^^^^^^^^^^^^
  File "/usr/local/lib/python3.12/site-packages/sqlalchemy/pool/base.py", line 1263, in _checkout
    fairy = _ConnectionRecord.checkout(pool)
            ^^^^^^^^^^^^^^^^^^^^^^^^^^^^^^^^
  File "/usr/local/lib/python3.12/site-packages/sqlalchemy/pool/base.py", line 712, in checkout
    rec = pool._do_get()
          ^^^^^^^^^^^^^^
  File "/usr/local/lib/python3.12/site-packages/sqlalchemy/pool/impl.py", line 179, in _do_get
    with util.safe_reraise():
         ^^^^^^^^^^^^^^^^^^^
  File "/usr/local/lib/python3.12/site-packages/sqlalchemy/util/langhelpers.py", line 146, in __exit__
    raise exc_value.with_traceback(exc_tb)
  File "/usr/local/lib/python3.12/site-packages/sqlalchemy/pool/impl.py", line 177, in _do_get
    return self._create_connection()
           ^^^^^^^^^^^^^^^^^^^^^^^^^
  File "/usr/local/lib/python3.12/site-packages/sqlalchemy/pool/base.py", line 390, in _create_connection
    return _ConnectionRecord(self)
           ^^^^^^^^^^^^^^^^^^^^^^^
  File "/usr/local/lib/python3.12/site-packages/sqlalchemy/pool/base.py", line 674, in __init__
    self.__connect()
  File "/usr/local/lib/python3.12/site-packages/sqlalchemy/pool/base.py", line 900, in __connect
    with util.safe_reraise():
         ^^^^^^^^^^^^^^^^^^^
  File "/usr/local/lib/python3.12/site-packages/sqlalchemy/util/langhelpers.py", line 146, in __exit__
    raise exc_value.with_traceback(exc_tb)
  File "/usr/local/lib/python3.12/site-packages/sqlalchemy/pool/base.py", line 896, in __connect
    self.dbapi_connection = connection = pool._invoke_creator(self)
                                         ^^^^^^^^^^^^^^^^^^^^^^^^^^
  File "/usr/local/lib/python3.12/site-packages/sqlalchemy/engine/create.py", line 643, in connect
    return dialect.connect(*cargs, **cparams)
           ^^^^^^^^^^^^^^^^^^^^^^^^^^^^^^^^^^
  File "/usr/local/lib/python3.12/site-packages/sqlalchemy/engine/default.py", line 621, in connect
    return self.loaded_dbapi.connect(*cargs, **cparams)
           ^^^^^^^^^^^^^^^^^^^^^^^^^^^^^^^^^^^^^^^^^^^^
  File "/usr/local/lib/python3.12/site-packages/psycopg2/__init__.py", line 122, in connect
    conn = _connect(dsn, connection_factory=connection_factory, **kwasync)
           ^^^^^^^^^^^^^^^^^^^^^^^^^^^^^^^^^^^^^^^^^^^^^^^^^^^^^^^^^^^^^^^
psycopg2.OperationalError: connection to server at "postgres" (172.18.0.3), port 5432 failed: FATAL:  password authentication failed for user "dt_user"


The above exception was the direct cause of the following exception:

Traceback (most recent call last):
  File "/app/Digital_Twin/AI_MODULES/mqtt_ingestor.py", line 127, in init_database_connection
    with db_engine.connect():
         ^^^^^^^^^^^^^^^^^^^
  File "/usr/local/lib/python3.12/site-packages/sqlalchemy/engine/base.py", line 3278, in connect
    return self._connection_cls(self)
           ^^^^^^^^^^^^^^^^^^^^^^^^^^
  File "/usr/local/lib/python3.12/site-packages/sqlalchemy/engine/base.py", line 148, in __init__
    Connection._handle_dbapi_exception_noconnection(
  File "/usr/local/lib/python3.12/site-packages/sqlalchemy/engine/base.py", line 2442, in _handle_dbapi_exception_noconnection
    raise sqlalchemy_exception.with_traceback(exc_info[2]) from e
  File "/usr/local/lib/python3.12/site-packages/sqlalchemy/engine/base.py", line 146, in __init__
    self._dbapi_connection = engine.raw_connection()
                             ^^^^^^^^^^^^^^^^^^^^^^^
  File "/usr/local/lib/python3.12/site-packages/sqlalchemy/engine/base.py", line 3302, in raw_connection
    return self.pool.connect()
           ^^^^^^^^^^^^^^^^^^^
  File "/usr/local/lib/python3.12/site-packages/sqlalchemy/pool/base.py", line 449, in connect
    return _ConnectionFairy._checkout(self)
           ^^^^^^^^^^^^^^^^^^^^^^^^^^^^^^^^
  File "/usr/local/lib/python3.12/site-packages/sqlalchemy/pool/base.py", line 1263, in _checkout
    fairy = _ConnectionRecord.checkout(pool)
            ^^^^^^^^^^^^^^^^^^^^^^^^^^^^^^^^
  File "/usr/local/lib/python3.12/site-packages/sqlalchemy/pool/base.py", line 712, in checkout
    rec = pool._do_get()
          ^^^^^^^^^^^^^^
  File "/usr/local/lib/python3.12/site-packages/sqlalchemy/pool/impl.py", line 179, in _do_get
    with util.safe_reraise():
         ^^^^^^^^^^^^^^^^^^^
  File "/usr/local/lib/python3.12/site-packages/sqlalchemy/util/langhelpers.py", line 146, in __exit__
    raise exc_value.with_traceback(exc_tb)
  File "/usr/local/lib/python3.12/site-packages/sqlalchemy/pool/impl.py", line 177, in _do_get
    return self._create_connection()
           ^^^^^^^^^^^^^^^^^^^^^^^^^
  File "/usr/local/lib/python3.12/site-packages/sqlalchemy/pool/base.py", line 390, in _create_connection
    return _ConnectionRecord(self)
           ^^^^^^^^^^^^^^^^^^^^^^^
  File "/usr/local/lib/python3.12/site-packages/sqlalchemy/pool/base.py", line 674, in __init__
    self.__connect()
  File "/usr/local/lib/python3.12/site-packages/sqlalchemy/pool/base.py", line 900, in __connect
    with util.safe_reraise():
         ^^^^^^^^^^^^^^^^^^^
  File "/usr/local/lib/python3.12/site-packages/sqlalchemy/util/langhelpers.py", line 146, in __exit__
    raise exc_value.with_traceback(exc_tb)
  File "/usr/local/lib/python3.12/site-packages/sqlalchemy/pool/base.py", line 896, in __connect
    self.dbapi_connection = connection = pool._invoke_creator(self)
                                         ^^^^^^^^^^^^^^^^^^^^^^^^^^
  File "/usr/local/lib/python3.12/site-packages/sqlalchemy/engine/create.py", line 643, in connect
    return dialect.connect(*cargs, **cparams)
           ^^^^^^^^^^^^^^^^^^^^^^^^^^^^^^^^^^
  File "/usr/local/lib/python3.12/site-packages/sqlalchemy/engine/default.py", line 621, in connect
    return self.loaded_dbapi.connect(*cargs, **cparams)
           ^^^^^^^^^^^^^^^^^^^^^^^^^^^^^^^^^^^^^^^^^^^^
  File "/usr/local/lib/python3.12/site-packages/psycopg2/__init__.py", line 122, in connect
    conn = _connect(dsn, connection_factory=connection_factory, **kwasync)
           ^^^^^^^^^^^^^^^^^^^^^^^^^^^^^^^^^^^^^^^^^^^^^^^^^^^^^^^^^^^^^^^
sqlalchemy.exc.OperationalError: (psycopg2.OperationalError) connection to server at "postgres" (172.18.0.3), port 5432 failed: FATAL:  password authentication failed for user "dt_user"

(Background on this error at: https://sqlalche.me/e/20/e3q8)
2025-10-31 03:36:59,531 - MQTTIngestor - CRITICAL - Database connection failed. Exiting.
2025-10-31 03:37:51,644 - MQTTIngestor - INFO - Starting MQTT Ingestor...
2025-10-31 03:37:51,690 - MQTTIngestor - CRITICAL - Failed to connect to database using SQLAlchemy: (psycopg2.OperationalError) connection to server at "postgres" (172.18.0.3), port 5432 failed: FATAL:  password authentication failed for user "dt_user"

(Background on this error at: https://sqlalche.me/e/20/e3q8)
Traceback (most recent call last):
  File "/usr/local/lib/python3.12/site-packages/sqlalchemy/engine/base.py", line 146, in __init__
    self._dbapi_connection = engine.raw_connection()
                             ^^^^^^^^^^^^^^^^^^^^^^^
  File "/usr/local/lib/python3.12/site-packages/sqlalchemy/engine/base.py", line 3302, in raw_connection
    return self.pool.connect()
           ^^^^^^^^^^^^^^^^^^^
  File "/usr/local/lib/python3.12/site-packages/sqlalchemy/pool/base.py", line 449, in connect
    return _ConnectionFairy._checkout(self)
           ^^^^^^^^^^^^^^^^^^^^^^^^^^^^^^^^
  File "/usr/local/lib/python3.12/site-packages/sqlalchemy/pool/base.py", line 1263, in _checkout
    fairy = _ConnectionRecord.checkout(pool)
            ^^^^^^^^^^^^^^^^^^^^^^^^^^^^^^^^
  File "/usr/local/lib/python3.12/site-packages/sqlalchemy/pool/base.py", line 712, in checkout
    rec = pool._do_get()
          ^^^^^^^^^^^^^^
  File "/usr/local/lib/python3.12/site-packages/sqlalchemy/pool/impl.py", line 179, in _do_get
    with util.safe_reraise():
         ^^^^^^^^^^^^^^^^^^^
  File "/usr/local/lib/python3.12/site-packages/sqlalchemy/util/langhelpers.py", line 146, in __exit__
    raise exc_value.with_traceback(exc_tb)
  File "/usr/local/lib/python3.12/site-packages/sqlalchemy/pool/impl.py", line 177, in _do_get
    return self._create_connection()
           ^^^^^^^^^^^^^^^^^^^^^^^^^
  File "/usr/local/lib/python3.12/site-packages/sqlalchemy/pool/base.py", line 390, in _create_connection
    return _ConnectionRecord(self)
           ^^^^^^^^^^^^^^^^^^^^^^^
  File "/usr/local/lib/python3.12/site-packages/sqlalchemy/pool/base.py", line 674, in __init__
    self.__connect()
  File "/usr/local/lib/python3.12/site-packages/sqlalchemy/pool/base.py", line 900, in __connect
    with util.safe_reraise():
         ^^^^^^^^^^^^^^^^^^^
  File "/usr/local/lib/python3.12/site-packages/sqlalchemy/util/langhelpers.py", line 146, in __exit__
    raise exc_value.with_traceback(exc_tb)
  File "/usr/local/lib/python3.12/site-packages/sqlalchemy/pool/base.py", line 896, in __connect
    self.dbapi_connection = connection = pool._invoke_creator(self)
                                         ^^^^^^^^^^^^^^^^^^^^^^^^^^
  File "/usr/local/lib/python3.12/site-packages/sqlalchemy/engine/create.py", line 643, in connect
    return dialect.connect(*cargs, **cparams)
           ^^^^^^^^^^^^^^^^^^^^^^^^^^^^^^^^^^
  File "/usr/local/lib/python3.12/site-packages/sqlalchemy/engine/default.py", line 621, in connect
    return self.loaded_dbapi.connect(*cargs, **cparams)
           ^^^^^^^^^^^^^^^^^^^^^^^^^^^^^^^^^^^^^^^^^^^^
  File "/usr/local/lib/python3.12/site-packages/psycopg2/__init__.py", line 122, in connect
    conn = _connect(dsn, connection_factory=connection_factory, **kwasync)
           ^^^^^^^^^^^^^^^^^^^^^^^^^^^^^^^^^^^^^^^^^^^^^^^^^^^^^^^^^^^^^^^
psycopg2.OperationalError: connection to server at "postgres" (172.18.0.3), port 5432 failed: FATAL:  password authentication failed for user "dt_user"


The above exception was the direct cause of the following exception:

Traceback (most recent call last):
  File "/app/Digital_Twin/AI_MODULES/mqtt_ingestor.py", line 127, in init_database_connection
    with db_engine.connect():
         ^^^^^^^^^^^^^^^^^^^
  File "/usr/local/lib/python3.12/site-packages/sqlalchemy/engine/base.py", line 3278, in connect
    return self._connection_cls(self)
           ^^^^^^^^^^^^^^^^^^^^^^^^^^
  File "/usr/local/lib/python3.12/site-packages/sqlalchemy/engine/base.py", line 148, in __init__
    Connection._handle_dbapi_exception_noconnection(
  File "/usr/local/lib/python3.12/site-packages/sqlalchemy/engine/base.py", line 2442, in _handle_dbapi_exception_noconnection
    raise sqlalchemy_exception.with_traceback(exc_info[2]) from e
  File "/usr/local/lib/python3.12/site-packages/sqlalchemy/engine/base.py", line 146, in __init__
    self._dbapi_connection = engine.raw_connection()
                             ^^^^^^^^^^^^^^^^^^^^^^^
  File "/usr/local/lib/python3.12/site-packages/sqlalchemy/engine/base.py", line 3302, in raw_connection
    return self.pool.connect()
           ^^^^^^^^^^^^^^^^^^^
  File "/usr/local/lib/python3.12/site-packages/sqlalchemy/pool/base.py", line 449, in connect
    return _ConnectionFairy._checkout(self)
           ^^^^^^^^^^^^^^^^^^^^^^^^^^^^^^^^
  File "/usr/local/lib/python3.12/site-packages/sqlalchemy/pool/base.py", line 1263, in _checkout
    fairy = _ConnectionRecord.checkout(pool)
            ^^^^^^^^^^^^^^^^^^^^^^^^^^^^^^^^
  File "/usr/local/lib/python3.12/site-packages/sqlalchemy/pool/base.py", line 712, in checkout
    rec = pool._do_get()
          ^^^^^^^^^^^^^^
  File "/usr/local/lib/python3.12/site-packages/sqlalchemy/pool/impl.py", line 179, in _do_get
    with util.safe_reraise():
         ^^^^^^^^^^^^^^^^^^^
  File "/usr/local/lib/python3.12/site-packages/sqlalchemy/util/langhelpers.py", line 146, in __exit__
    raise exc_value.with_traceback(exc_tb)
  File "/usr/local/lib/python3.12/site-packages/sqlalchemy/pool/impl.py", line 177, in _do_get
    return self._create_connection()
           ^^^^^^^^^^^^^^^^^^^^^^^^^
  File "/usr/local/lib/python3.12/site-packages/sqlalchemy/pool/base.py", line 390, in _create_connection
    return _ConnectionRecord(self)
           ^^^^^^^^^^^^^^^^^^^^^^^
  File "/usr/local/lib/python3.12/site-packages/sqlalchemy/pool/base.py", line 674, in __init__
    self.__connect()
  File "/usr/local/lib/python3.12/site-packages/sqlalchemy/pool/base.py", line 900, in __connect
    with util.safe_reraise():
         ^^^^^^^^^^^^^^^^^^^
  File "/usr/local/lib/python3.12/site-packages/sqlalchemy/util/langhelpers.py", line 146, in __exit__
    raise exc_value.with_traceback(exc_tb)
  File "/usr/local/lib/python3.12/site-packages/sqlalchemy/pool/base.py", line 896, in __connect
    self.dbapi_connection = connection = pool._invoke_creator(self)
                                         ^^^^^^^^^^^^^^^^^^^^^^^^^^
  File "/usr/local/lib/python3.12/site-packages/sqlalchemy/engine/create.py", line 643, in connect
    return dialect.connect(*cargs, **cparams)
           ^^^^^^^^^^^^^^^^^^^^^^^^^^^^^^^^^^
  File "/usr/local/lib/python3.12/site-packages/sqlalchemy/engine/default.py", line 621, in connect
    return self.loaded_dbapi.connect(*cargs, **cparams)
           ^^^^^^^^^^^^^^^^^^^^^^^^^^^^^^^^^^^^^^^^^^^^
  File "/usr/local/lib/python3.12/site-packages/psycopg2/__init__.py", line 122, in connect
    conn = _connect(dsn, connection_factory=connection_factory, **kwasync)
           ^^^^^^^^^^^^^^^^^^^^^^^^^^^^^^^^^^^^^^^^^^^^^^^^^^^^^^^^^^^^^^^
sqlalchemy.exc.OperationalError: (psycopg2.OperationalError) connection to server at "postgres" (172.18.0.3), port 5432 failed: FATAL:  password authentication failed for user "dt_user"

(Background on this error at: https://sqlalche.me/e/20/e3q8)
2025-10-31 03:37:51,695 - MQTTIngestor - CRITICAL - Database connection failed. Exiting.
2025-10-31 03:43:36,104 - MQTTIngestor - INFO - Starting MQTT Ingestor...
2025-10-31 03:43:36,184 - MQTTIngestor - INFO - SQLAlchemy connected to database via engine.
2025-10-31 03:43:36,258 - MQTTIngestor - INFO - Table 'device_readings' not found, creating...
2025-10-31 03:43:36,367 - MQTTIngestor - INFO - Table 'device_readings' created.
2025-10-31 03:43:36,389 - MQTTIngestor - INFO - Prometheus metrics server started on port 8001
2025-10-31 03:43:36,398 - MQTTIngestor - INFO - Attempting connection to MQTT broker mosquitto:1883...
2025-10-31 03:43:44,368 - MQTTIngestor - ERROR - Initial connection failed: [Errno -2] Name or service not known. Will attempt reconnection.
2025-10-31 03:43:44,371 - MQTTIngestor - INFO - Scheduling reconnection attempt 1 in 5 seconds...
2025-10-31 03:43:57,259 - MQTTIngestor - ERROR - Reconnect attempt failed: [Errno -2] Name or service not known
2025-10-31 03:43:57,261 - MQTTIngestor - INFO - Scheduling reconnection attempt 2 in 10 seconds...
2025-10-31 03:44:15,180 - MQTTIngestor - ERROR - Reconnect attempt failed: [Errno -2] Name or service not known
2025-10-31 03:44:15,191 - MQTTIngestor - INFO - Scheduling reconnection attempt 3 in 20 seconds...
2025-10-31 03:44:43,133 - MQTTIngestor - ERROR - Reconnect attempt failed: [Errno -2] Name or service not known
2025-10-31 03:44:43,137 - MQTTIngestor - INFO - Scheduling reconnection attempt 4 in 40 seconds...
2025-10-31 03:45:31,107 - MQTTIngestor - ERROR - Reconnect attempt failed: [Errno -2] Name or service not known
2025-10-31 03:45:31,140 - MQTTIngestor - INFO - Scheduling reconnection attempt 5 in 80 seconds...
2025-10-31 03:51:12,604 - MQTTIngestor - INFO - Starting MQTT Ingestor...
2025-10-31 03:51:12,651 - MQTTIngestor - INFO - SQLAlchemy connected to database via engine.
2025-10-31 03:51:12,750 - MQTTIngestor - INFO - Table 'device_readings' already exists.
2025-10-31 03:51:12,755 - MQTTIngestor - INFO - Prometheus metrics server started on port 8001
2025-10-31 03:51:12,755 - MQTTIngestor - INFO - Attempting connection to MQTT broker mosquitto:1883...
2025-10-31 03:51:20,683 - MQTTIngestor - ERROR - Initial connection failed: [Errno -2] Name or service not known. Will attempt reconnection.
2025-10-31 03:51:20,685 - MQTTIngestor - INFO - Scheduling reconnection attempt 1 in 5 seconds...
2025-10-31 03:51:33,548 - MQTTIngestor - ERROR - Reconnect attempt failed: [Errno -2] Name or service not known
2025-10-31 03:51:33,549 - MQTTIngestor - INFO - Scheduling reconnection attempt 2 in 10 seconds...
2025-10-31 03:51:51,551 - MQTTIngestor - ERROR - Reconnect attempt failed: [Errno -3] Temporary failure in name resolution
2025-10-31 03:51:51,573 - MQTTIngestor - INFO - Scheduling reconnection attempt 3 in 20 seconds...
2025-10-31 03:52:19,522 - MQTTIngestor - ERROR - Reconnect attempt failed: [Errno -2] Name or service not known
2025-10-31 03:52:19,537 - MQTTIngestor - INFO - Scheduling reconnection attempt 4 in 40 seconds...
2025-10-31 03:53:03,556 - MQTTIngestor - ERROR - Reconnect attempt failed: [Errno -2] Name or service not known
2025-10-31 03:53:03,557 - MQTTIngestor - INFO - Scheduling reconnection attempt 5 in 80 seconds...
2025-10-31 03:54:17,700 - MQTTIngestor - INFO - Starting MQTT Ingestor...
2025-10-31 03:54:17,752 - MQTTIngestor - INFO - SQLAlchemy connected to database via engine.
2025-10-31 03:54:17,831 - MQTTIngestor - INFO - Table 'device_readings' already exists.
2025-10-31 03:54:17,835 - MQTTIngestor - INFO - Prometheus metrics server started on port 8001
2025-10-31 03:54:17,841 - MQTTIngestor - INFO - Attempting connection to MQTT broker mosquitto:1883...
2025-10-31 03:54:21,886 - MQTTIngestor - ERROR - Initial connection failed: [Errno 111] Connection refused. Will attempt reconnection.
2025-10-31 03:54:21,890 - MQTTIngestor - INFO - Scheduling reconnection attempt 1 in 5 seconds...
2025-10-31 03:54:34,783 - MQTTIngestor - ERROR - Reconnect attempt failed: [Errno -2] Name or service not known
2025-10-31 03:54:34,786 - MQTTIngestor - INFO - Scheduling reconnection attempt 2 in 10 seconds...
2025-10-31 03:54:52,660 - MQTTIngestor - ERROR - Reconnect attempt failed: [Errno -2] Name or service not known
2025-10-31 03:54:52,661 - MQTTIngestor - INFO - Scheduling reconnection attempt 3 in 20 seconds...
2025-10-31 03:55:20,530 - MQTTIngestor - ERROR - Reconnect attempt failed: [Errno -2] Name or service not known
2025-10-31 03:55:20,532 - MQTTIngestor - INFO - Scheduling reconnection attempt 4 in 40 seconds...
2025-10-31 03:56:08,388 - MQTTIngestor - ERROR - Reconnect attempt failed: [Errno -2] Name or service not known
2025-10-31 03:56:08,395 - MQTTIngestor - INFO - Scheduling reconnection attempt 5 in 80 seconds...
2025-10-31 03:57:36,256 - MQTTIngestor - ERROR - Reconnect attempt failed: [Errno -2] Name or service not known
2025-10-31 03:57:36,258 - MQTTIngestor - INFO - Scheduling reconnection attempt 6 in 160 seconds...
